Workbook
Name Acc1_: Sheet1!$B$29
Name Acc1単価: Sheet1!$B$22
Name Acc2_: Sheet1!$B$30
Name Acc2単価: Sheet1!$B$23
Name Acc3_: Sheet1!$B$31
Name Acc3単価: Sheet1!$B$24
Name CPU1_: Sheet1!$B$25
Name CPU1単価: Sheet1!$B$18
Name CPU2_: Sheet1!$B$26
Name CPU2単価: Sheet1!$B$19
Name Mem1_: Sheet1!$B$27
Name Mem1単価: Sheet1!$B$20
Name Mem2_: Sheet1!$B$28
Name Mem2単価: Sheet1!$B$21
Name サービス: Sheet1!$A$1:$A$5
Name ストレージ一般解析Quota設定のみ: Sheet1!$A$9
Name ストレージ一般解析Quota設定のみ単価: Sheet1!$B$15
Name ストレージ個人ゲノムQuota設定のみ: Sheet1!$A$10
Name ストレージ個人ゲノムQuota設定のみ基本料金: Sheet1!$B$17
Name ストレージ個人ゲノムQuota設定のみ単価: Sheet1!$B$16
Name ストレージ大規模利用_一般解析区画: Sheet1!$B$1
Name ストレージ大規模利用_個人ゲノム区画: Sheet1!$B$2
Name 計算ノードGPU専用Slurm_個人ゲノム区画: Sheet1!$B$5
Name 計算ノード占有利用_一般解析区画: Sheet1!$B$3:$D$3
Name 計算ノード占有利用_個人ゲノム区画: Sheet1!$B$4:$G$4
Name 計算ノード優先利用_一般解析区画: Sheet1!$B$6:$H$6
Name 計算ノード優先利用_個人ゲノム区画: Sheet1!$B$7:$H$7
Name 消費税: Sheet1!$B$14
Name 年: 料金試算表!$A$1
Name 年間日数: Sheet1!$B$13

Sheet 利用目的等
G1: 申請日 | H1: 年 | I1: 月 | J1: 日
A2: １・責任者情報
A3: 責任者名
A4: 責任者アカウント名
A5: 責任者所属
A6: 責任者職名
A9: ２・研究プロジェクト名（プロジェクト名があれば記入してください）
A12: ３・ユーザー一覧 (※）グループは通常は責任者1名に対して１つ作られます。同一グループのユーザーは互いにファイルの読み書きが出来ます。ファイルアクセス制御のため責任者1名に対して複数のグループを作成したい場合は表の中に希望グループ名を記載してください。
A13: No. | B13: 氏名 | C13: E-mail | D13: 希望アカウント名 | E13: 希望グループ名（※） | F13: 所属・職名
A14: 1
A15: 2
A16: 3
A17: 4
A18: 5
A19: 6
A20: 7
A21: 8
A22: 9
A23: 10
A24: 11
A25: 12
... A29: 16
A31: ４・研究利用内容 (利用目的、利用するプログラム等)
A56: ５・利用リソース量の計画 (希望するリソース量および必要リソース量の見積方法)
A83: ６・その他の希望事項

Sheet 料金試算表
A1: 2026 | B1: 料金試算表
A2: 一般解析区画を利用し、ストレージ利用量が責任者あたりの合計で30TB以下の場合は無料となります。
A4: 申請日：
A5: 責任者名：
A6: 責任者アカウント：
A7: 責任者所属：
A8: 開始日 | B8: 終了日 | C8: サービス | D8: 種別 | E8: アカウント名またはグループ名 | O8: リソース量合計 | P8: サービス種別 | Q8: リソース量合計 | R8: 第一期日数 | S8: 第二期日数 | T8: 第三期日数 | U8: 第一期料金 (消費税込み) | V8: 第二期料金 (消費税込み) | W8: 第三期料金 (消費税込み)
E9: 氏名
A12: 46113 | B12: 46477 | C12: ストレージ大規模利用_一般解析区画 | D12: Quota設定のみ | O12: =IF( AND(SUM(E12:N12)>0,OR(C12=Sheet1!$A$1,C12=Sheet1!$A$2)), CONCATENATE(SUM(E12:N12),"TB"), IF( AND(SUM(E12:N12)>0,OR(C12=Sheet1!$A$6,C12=Sheet1!$A$3,C12=Sheet1!$A$7,C12=Sheet1!$A$4),D12=Sheet1!$B$31), CONCATENATE(SUM(E12:N12),"台"), IF( AND( SUM(E12:N12)>0, OR(C12=Sheet1!$A$6,C12=Sheet1!$A$3,C12=Sheet1!$A$7,C12=Sheet1!$A$4,C12=Sheet1!$A$5), OR(D12=Sheet1!$B$25,D12=Sheet1!$B$26,D12=Sheet1!$B$27,D12=Sheet1!$B$28,D12=Sheet1!$B$29,D12=Sheet1!$B$30) ), CONCATENATE(SUM(E12:N12),"単位"), "" ) ) ) | P12: =C12&D12 -> ストレージ大規模利用_一般解析区画Quota設定のみ | Q12: =SUM(E12:N12) -> 0 | R12: =IF(AND($A12<=DATE(年,4,1),$B12>=DATE(年,7,31)),DATEDIF(DATE(年,4,1),DATE(年,7,31),"d")+1,IF(AND($A12>DATE(年,4,1),$A12<=DATE(年,7,31),$B12>=DATE(年,7,31)),DATEDIF($A12,DATE(年,7,31),"d")+1,IF(AND($A12<=DATE(年,4,1),$B12>=DATE(年,4,1),$B12<=DATE(年,7,31)),DATEDIF(DATE(年,4,1),$B12,"d")+1,IF(AND($A12>=DATE(年,4,1),$A12<=DATE(年,7,31),$B12>=DATE(年,4,1),$B12<=DATE(年,7,31)),DATEDIF(A12,B12,"d")+1,0)))) -> 122 | S12: =IF(AND($A12<=DATE(年,8,1),$B12>=DATE(年,11,30)),DATEDIF(DATE(年,8,1),DATE(年,11,30),"d")+1,IF(AND($A12>DATE(年,8,1),$A12<=DATE(年,11,30),$B12>=DATE(年,11,30)),DATEDIF($A12,DATE(年,11,30),"d")+1,IF(AND($A12<=DATE(年,8,1),$B12>=DATE(年,8,1),$B12<=DATE(年,11,30)),DATEDIF(DATE(年,8,1),$B12,"d")+1,IF(AND($A12>=DATE(年,8,1),$A12<=DATE(年,11,30),$B12>=DATE(年,8,1),$B12<=DATE(年,11,30)),DATEDIF($A12,$B12,"d")+1,0)))) -> 122 | T12: =IF(AND($A12<=DATE(年,12,1),$B12>=DATE(年+1,3,31)),DATEDIF(DATE(年,12,1),DATE(年+1,3,31),"d")+1,IF(AND($A12>DATE(年,12,1),$A12<=DATE(年+1,3,31),$B12>=DATE(年+1,3,31)),DATEDIF($A12,DATE(年+1,3,31),"d")+1,IF(AND($A12<=DATE(年,12,1),$B12>=DATE(年,12,1),$B12<=DATE(年+1,3,31)),DATEDIF(DATE(年,12,1),$B12,"d")+1,IF(AND(A12>=DATE(年,12,1),$A12<=DATE(年+1,3,31),$B12>=DATE(年,12,1),$B12<=DATE(年+1,3,31)),DATEDIF($A12,$B12,"d")+1,0)))) -> 121 | U12: =IF( AND($P12=ストレージ一般解析Quota設定のみ,$Q12<=30),0,IF( AND($P12=ストレージ一般解析Quota設定のみ,$Q12>30),ROUNDDOWN(ROUNDDOWN(ROUNDUP($Q12/10,0)*ストレージ一般解析Quota設定のみ単価*(R12/年間日数),0)*消費税,0),IF( AND($P12=ストレージ個人ゲノムQuota設定のみ),ROUNDDOWN(ROUNDDOWN(ROUNDUP($Q12/10,0)*ストレージ個人ゲノムQuota設定のみ単価*(R12/年間日数),0)*消費税,0),IF( $D12=CPU1_,ROUNDDOWN(ROUNDDOWN(($Q12*CPU1単価*R12/30),0)*消費税,0),IF( $D12=CPU2_,ROUNDDOWN(ROUNDDOWN(($Q12*CPU2単価*R12/30),0)*消費税,0),IF( $D12=Mem1_,ROUNDDOWN(ROUNDDOWN(($Q12*Mem1単価*R12/30),0)*消費税,0),IF( $D12=Mem2_,ROUNDDOWN(ROUNDDOWN(($Q12*Mem2単価*R12/30),0)*消費税,0),IF( $D12=Acc1_,ROUNDDOWN(ROUNDDOWN(($Q12*Acc1単価*R12/30),0)*消費税,0),IF( $D12=Acc2_,ROUNDDOWN(ROUNDDOWN(($Q12*Acc2単価*R12/30),0)*消費税,0),IF( $D12=Acc3_,ROUNDDOWN(ROUNDDOWN(($Q12*Acc3単価*R12/30),0)*消費税,0),"" ) ) ) ) ) ) ) ) ) ) -> 0 | V12: =IF( AND($P12=ストレージ一般解析Quota設定のみ,$Q12<=30),0,IF( AND($P12=ストレージ一般解析Quota設定のみ,$Q12>30),ROUNDDOWN(ROUNDDOWN(ROUNDUP($Q12/10,0)*ストレージ一般解析Quota設定のみ単価*(S12/年間日数),0)*消費税,0),IF( AND($P12=ストレージ個人ゲノムQuota設定のみ),ROUNDDOWN(ROUNDDOWN(ROUNDUP($Q12/10,0)*ストレージ個人ゲノムQuota設定のみ単価*(S12/年間日数),0)*消費税,0),IF( $D12=CPU1_,ROUNDDOWN(ROUNDDOWN(($Q12*CPU1単価*S12/30),0)*消費税,0),IF( $D12=CPU2_,ROUNDDOWN(ROUNDDOWN(($Q12*CPU2単価*S12/30),0)*消費税,0),IF( $D12=Mem1_,ROUNDDOWN(ROUNDDOWN(($Q12*Mem1単価*S12/30),0)*消費税,0),IF( $D12=Mem2_,ROUNDDOWN(ROUNDDOWN(($Q12*Mem2単価*S12/30),0)*消費税,0),IF( $D12=Acc1_,ROUNDDOWN(ROUNDDOWN(($Q12*Acc1単価*S12/30),0)*消費税,0),IF( $D12=Acc2_,ROUNDDOWN(ROUNDDOWN(($Q12*Acc2単価*S12/30),0)*消費税,0),IF( $D12=Acc3_,ROUNDDOWN(ROUNDDOWN(($Q12*Acc3単価*S12/30),0)*消費税,0),"" ) ) ) ) ) ) ) ) ) ) -> 0 | W12: =IF( AND($P12=ストレージ一般解析Quota設定のみ,$Q12<=30),0,IF( AND($P12=ストレージ一般解析Quota設定のみ,$Q12>30),ROUNDDOWN(ROUNDDOWN(ROUNDUP($Q12/10,0)*ストレージ一般解析Quota設定のみ単価*(T12/年間日数),0)*消費税,0),IF( AND($P12=ストレージ個人ゲノムQuota設定のみ),ROUNDDOWN(ROUNDDOWN(ROUNDUP($Q12/10,0)*ストレージ個人ゲノムQuota設定のみ単価*(T12/年間日数),0)*消費税,0),IF( $D12=CPU1_,ROUNDDOWN(ROUNDDOWN(($Q12*CPU1単価*T12/30),0)*消費税,0),IF( $D12=CPU2_,ROUNDDOWN(ROUNDDOWN(($Q12*CPU2単価*T12/30),0)*消費税,0),IF( $D12=Mem1_,ROUNDDOWN(ROUNDDOWN(($Q12*Mem1単価*T12/30),0)*消費税,0),IF( $D12=Mem2_,ROUNDDOWN(ROUNDDOWN(($Q12*Mem2単価*T12/30),0)*消費税,0),IF( $D12=Acc1_,ROUNDDOWN(ROUNDDOWN(($Q12*Acc1単価*T12/30),0)*消費税,0),IF( $D12=Acc2_,ROUNDDOWN(ROUNDDOWN(($Q12*Acc2単価*T12/30),0)*消費税,0),IF( $D12=Acc3_,ROUNDDOWN(ROUNDDOWN(($Q12*Acc3単価*T12/30),0)*消費税,0),"" ) ) ) ) ) ) ) ) ) ) -> 0
O13: =IF( AND(SUM(E13:N13)>0,OR(C13=Sheet1!$A$1,C13=Sheet1!$A$2)), CONCATENATE(SUM(E13:N13),"TB"), IF( AND(SUM(E13:N13)>0,OR(C13=Sheet1!$A$6,C13=Sheet1!$A$3,C13=Sheet1!$A$7,C13=Sheet1!$A$4),D13=Sheet1!$B$31), CONCATENATE(SUM(E13:N13),"台"), IF( AND( SUM(E13:N13)>0, OR(C13=Sheet1!$A$6,C13=Sheet1!$A$3,C13=Sheet1!$A$7,C13=Sheet1!$A$4,C13=Sheet1!$A$5), OR(D13=Sheet1!$B$25,D13=Sheet1!$B$26,D13=Sheet1!$B$27,D13=Sheet1!$B$28,D13=Sheet1!$B$29,D13=Sheet1!$B$30) ), CONCATENATE(SUM(E13:N13),"単位"), "" ) ) ) | P13: =C13&D13 | Q13: =SUM(E13:N13) -> 0 | R13: =IF(AND($A13<=DATE(年,4,1),$B13>=DATE(年,7,31)),DATEDIF(DATE(年,4,1),DATE(年,7,31),"d")+1,IF(AND($A13>DATE(年,4,1),$A13<=DATE(年,7,31),$B13>=DATE(年,7,31)),DATEDIF($A13,DATE(年,7,31),"d")+1,IF(AND($A13<=DATE(年,4,1),$B13>=DATE(年,4,1),$B13<=DATE(年,7,31)),DATEDIF(DATE(年,4,1),$B13,"d")+1,IF(AND($A13>=DATE(年,4,1),$A13<=DATE(年,7,31),$B13>=DATE(年,4,1),$B13<=DATE(年,7,31)),DATEDIF(A13,B13,"d")+1,0)))) -> 0 | S13: =IF(AND($A13<=DATE(年,8,1),$B13>=DATE(年,11,30)),DATEDIF(DATE(年,8,1),DATE(年,11,30),"d")+1,IF(AND($A13>DATE(年,8,1),$A13<=DATE(年,11,30),$B13>=DATE(年,11,30)),DATEDIF($A13,DATE(年,11,30),"d")+1,IF(AND($A13<=DATE(年,8,1),$B13>=DATE(年,8,1),$B13<=DATE(年,11,30)),DATEDIF(DATE(年,8,1),$B13,"d")+1,IF(AND($A13>=DATE(年,8,1),$A13<=DATE(年,11,30),$B13>=DATE(年,8,1),$B13<=DATE(年,11,30)),DATEDIF($A13,$B13,"d")+1,0)))) -> 0 | T13: =IF(AND($A13<=DATE(年,12,1),$B13>=DATE(年+1,3,31)),DATEDIF(DATE(年,12,1),DATE(年+1,3,31),"d")+1,IF(AND($A13>DATE(年,12,1),$A13<=DATE(年+1,3,31),$B13>=DATE(年+1,3,31)),DATEDIF($A13,DATE(年+1,3,31),"d")+1,IF(AND($A13<=DATE(年,12,1),$B13>=DATE(年,12,1),$B13<=DATE(年+1,3,31)),DATEDIF(DATE(年,12,1),$B13,"d")+1,IF(AND(A13>=DATE(年,12,1),$A13<=DATE(年+1,3,31),$B13>=DATE(年,12,1),$B13<=DATE(年+1,3,31)),DATEDIF($A13,$B13,"d")+1,0)))) -> 0 | U13: =IF( AND($P13=ストレージ一般解析Quota設定のみ,$Q13<=30),0,IF( AND($P13=ストレージ一般解析Quota設定のみ,$Q13>30),ROUNDDOWN(ROUNDDOWN(ROUNDUP($Q13/10,0)*ストレージ一般解析Quota設定のみ単価*(R13/年間日数),0)*消費税,0),IF( AND($P13=ストレージ個人ゲノムQuota設定のみ),ROUNDDOWN(ROUNDDOWN(ROUNDUP($Q13/10,0)*ストレージ個人ゲノムQuota設定のみ単価*(R13/年間日数),0)*消費税,0),IF( $D13=CPU1_,ROUNDDOWN(ROUNDDOWN(($Q13*CPU2単価*R13/30),0)*消費税,0),IF( $D13=CPU2_,ROUNDDOWN(ROUNDDOWN(($Q13*CPU3単価*R13/30),0)*消費税,0),IF( $D13=Mem1_,ROUNDDOWN(ROUNDDOWN(($Q13*Mem1単価*R13/30),0)*消費税,0),IF( $D13=Mem2_,ROUNDDOWN(ROUNDDOWN(($Q13*Mem2単価*R13/30),0)*消費税,0),IF( $D13=Acc1_,ROUNDDOWN(ROUNDDOWN(($Q13*Acc1単価*R13/30),0)*消費税,0),IF( $D13=Acc2_,ROUNDDOWN(ROUNDDOWN(($Q13*Acc2単価*R13/30),0)*消費税,0),IF( $D13=Acc3_,ROUNDDOWN(ROUNDDOWN(($Q13*Acc3単価*R13/30),0)*消費税,0),"" ) ) ) ) ) ) ) ) ) ) | V13: =IF( AND($P13=ストレージ一般解析Quota設定のみ,$Q13<=30),0,IF( AND($P13=ストレージ一般解析Quota設定のみ,$Q13>30),ROUNDDOWN(ROUNDDOWN(ROUNDUP($Q13/10,0)*ストレージ一般解析Quota設定のみ単価*(S13/年間日数),0)*消費税,0),IF( AND($P13=ストレージ個人ゲノムQuota設定のみ),ROUNDDOWN(ROUNDDOWN(ROUNDUP($Q13/10,0)*ストレージ個人ゲノムQuota設定のみ単価*(S13/年間日数),0)*消費税,0),IF( $D13=CPU1_,ROUNDDOWN(ROUNDDOWN(($Q13*CPU2単価*S13/30),0)*消費税,0),IF( $D13=CPU2_,ROUNDDOWN(ROUNDDOWN(($Q13*CPU3単価*S13/30),0)*消費税,0),IF( $D13=Mem1_,ROUNDDOWN(ROUNDDOWN(($Q13*Mem1単価*S13/30),0)*消費税,0),IF( $D13=Mem2_,ROUNDDOWN(ROUNDDOWN(($Q13*Mem2単価*S13/30),0)*消費税,0),IF( $D13=Acc1_,ROUNDDOWN(ROUNDDOWN(($Q13*Acc1単価*S13/30),0)*消費税,0),IF( $D13=Acc2_,ROUNDDOWN(ROUNDDOWN(($Q13*Acc2単価*S13/30),0)*消費税,0),IF( $D13=Acc3_,ROUNDDOWN(ROUNDDOWN(($Q13*Acc3単価*S13/30),0)*消費税,0),"" ) ) ) ) ) ) ) ) ) ) | W13: =IF( AND($P13=ストレージ一般解析Quota設定のみ,$Q13<=30),0,IF( AND($P13=ストレージ一般解析Quota設定のみ,$Q13>30),ROUNDDOWN(ROUNDDOWN(ROUNDUP($Q13/10,0)*ストレージ一般解析Quota設定のみ単価*(T13/年間日数),0)*消費税,0),IF( AND($P13=ストレージ個人ゲノムQuota設定のみ),ROUNDDOWN(ROUNDDOWN(ROUNDUP($Q13/10,0)*ストレージ個人ゲノムQuota設定のみ単価*(T13/年間日数),0)*消費税,0),IF( $D13=CPU1_,ROUNDDOWN(ROUNDDOWN(($Q13*CPU2単価*T13/30),0)*消費税,0),IF( $D13=CPU2_,ROUNDDOWN(ROUNDDOWN(($Q13*CPU3単価*T13/30),0)*消費税,0),IF( $D13=Mem1_,ROUNDDOWN(ROUNDDOWN(($Q13*Mem1単価*T13/30),0)*消費税,0),IF( $D13=Mem2_,ROUNDDOWN(ROUNDDOWN(($Q13*Mem2単価*T13/30),0)*消費税,0),IF( $D13=Acc1_,ROUNDDOWN(ROUNDDOWN(($Q13*Acc1単価*T13/30),0)*消費税,0),IF( $D13=Acc2_,ROUNDDOWN(ROUNDDOWN(($Q13*Acc2単価*T13/30),0)*消費税,0),IF( $D13=Acc3_,ROUNDDOWN(ROUNDDOWN(($Q13*Acc3単価*T13/30),0)*消費税,0),"" ) ) ) ) ) ) ) ) ) )
O14: =IF( AND(SUM(E14:N14)>0,OR(C14=Sheet1!$A$1,C14=Sheet1!$A$2)), CONCATENATE(SUM(E14:N14),"TB"), IF( AND(SUM(E14:N14)>0,OR(C14=Sheet1!$A$6,C14=Sheet1!$A$3,C14=Sheet1!$A$7,C14=Sheet1!$A$4),D14=Sheet1!$B$31), CONCATENATE(SUM(E14:N14),"台"), IF( AND( SUM(E14:N14)>0, OR(C14=Sheet1!$A$6,C14=Sheet1!$A$3,C14=Sheet1!$A$7,C14=Sheet1!$A$4,C14=Sheet1!$A$5), OR(D14=Sheet1!$B$25,D14=Sheet1!$B$26,D14=Sheet1!$B$27,D14=Sheet1!$B$28,D14=Sheet1!$B$29,D14=Sheet1!$B$30) ), CONCATENATE(SUM(E14:N14),"単位"), "" ) ) ) | P14: =C14&D14 | Q14: =SUM(E14:N14) -> 0 | R14: =IF(AND($A14<=DATE(年,4,1),$B14>=DATE(年,7,31)),DATEDIF(DATE(年,4,1),DATE(年,7,31),"d")+1,IF(AND($A14>DATE(年,4,1),$A14<=DATE(年,7,31),$B14>=DATE(年,7,31)),DATEDIF($A14,DATE(年,7,31),"d")+1,IF(AND($A14<=DATE(年,4,1),$B14>=DATE(年,4,1),$B14<=DATE(年,7,31)),DATEDIF(DATE(年,4,1),$B14,"d")+1,IF(AND($A14>=DATE(年,4,1),$A14<=DATE(年,7,31),$B14>=DATE(年,4,1),$B14<=DATE(年,7,31)),DATEDIF(A14,B14,"d")+1,0)))) -> 0 | S14: =IF(AND($A14<=DATE(年,8,1),$B14>=DATE(年,11,30)),DATEDIF(DATE(年,8,1),DATE(年,11,30),"d")+1,IF(AND($A14>DATE(年,8,1),$A14<=DATE(年,11,30),$B14>=DATE(年,11,30)),DATEDIF($A14,DATE(年,11,30),"d")+1,IF(AND($A14<=DATE(年,8,1),$B14>=DATE(年,8,1),$B14<=DATE(年,11,30)),DATEDIF(DATE(年,8,1),$B14,"d")+1,IF(AND($A14>=DATE(年,8,1),$A14<=DATE(年,11,30),$B14>=DATE(年,8,1),$B14<=DATE(年,11,30)),DATEDIF($A14,$B14,"d")+1,0)))) -> 0 | T14: =IF(AND($A14<=DATE(年,12,1),$B14>=DATE(年+1,3,31)),DATEDIF(DATE(年,12,1),DATE(年+1,3,31),"d")+1,IF(AND($A14>DATE(年,12,1),$A14<=DATE(年+1,3,31),$B14>=DATE(年+1,3,31)),DATEDIF($A14,DATE(年+1,3,31),"d")+1,IF(AND($A14<=DATE(年,12,1),$B14>=DATE(年,12,1),$B14<=DATE(年+1,3,31)),DATEDIF(DATE(年,12,1),$B14,"d")+1,IF(AND(A14>=DATE(年,12,1),$A14<=DATE(年+1,3,31),$B14>=DATE(年,12,1),$B14<=DATE(年+1,3,31)),DATEDIF($A14,$B14,"d")+1,0)))) -> 0 | U14: =IF( AND($P14=ストレージ一般解析Quota設定のみ,$Q14<=30),0,IF( AND($P14=ストレージ一般解析Quota設定のみ,$Q14>30),ROUNDDOWN(ROUNDDOWN(ROUNDUP($Q14/10,0)*ストレージ一般解析Quota設定のみ単価*(R14/年間日数),0)*消費税,0),IF( AND($P14=ストレージ個人ゲノムQuota設定のみ),ROUNDDOWN(ROUNDDOWN(ROUNDUP($Q14/10,0)*ストレージ個人ゲノムQuota設定のみ単価*(R14/年間日数),0)*消費税,0),IF( $D14=CPU1_,ROUNDDOWN(ROUNDDOWN(($Q14*CPU3単価*R14/30),0)*消費税,0),IF( $D14=CPU2_,ROUNDDOWN(ROUNDDOWN(($Q14*CPU4単価*R14/30),0)*消費税,0),IF( $D14=Mem1_,ROUNDDOWN(ROUNDDOWN(($Q14*Mem1単価*R14/30),0)*消費税,0),IF( $D14=Mem2_,ROUNDDOWN(ROUNDDOWN(($Q14*Mem2単価*R14/30),0)*消費税,0),IF( $D14=Acc1_,ROUNDDOWN(ROUNDDOWN(($Q14*Acc1単価*R14/30),0)*消費税,0),IF( $D14=Acc2_,ROUNDDOWN(ROUNDDOWN(($Q14*Acc2単価*R14/30),0)*消費税,0),IF( $D14=Acc3_,ROUNDDOWN(ROUNDDOWN(($Q14*Acc3単価*R14/30),0)*消費税,0),"" ) ) ) ) ) ) ) ) ) ) | V14: =IF( AND($P14=ストレージ一般解析Quota設定のみ,$Q14<=30),0,IF( AND($P14=ストレージ一般解析Quota設定のみ,$Q14>30),ROUNDDOWN(ROUNDDOWN(ROUNDUP($Q14/10,0)*ストレージ一般解析Quota設定のみ単価*(S14/年間日数),0)*消費税,0),IF( AND($P14=ストレージ個人ゲノムQuota設定のみ),ROUNDDOWN(ROUNDDOWN(ROUNDUP($Q14/10,0)*ストレージ個人ゲノムQuota設定のみ単価*(S14/年間日数),0)*消費税,0),IF( $D14=CPU1_,ROUNDDOWN(ROUNDDOWN(($Q14*CPU3単価*S14/30),0)*消費税,0),IF( $D14=CPU2_,ROUNDDOWN(ROUNDDOWN(($Q14*CPU4単価*S14/30),0)*消費税,0),IF( $D14=Mem1_,ROUNDDOWN(ROUNDDOWN(($Q14*Mem1単価*S14/30),0)*消費税,0),IF( $D14=Mem2_,ROUNDDOWN(ROUNDDOWN(($Q14*Mem2単価*S14/30),0)*消費税,0),IF( $D14=Acc1_,ROUNDDOWN(ROUNDDOWN(($Q14*Acc1単価*S14/30),0)*消費税,0),IF( $D14=Acc2_,ROUNDDOWN(ROUNDDOWN(($Q14*Acc2単価*S14/30),0)*消費税,0),IF( $D14=Acc3_,ROUNDDOWN(ROUNDDOWN(($Q14*Acc3単価*S14/30),0)*消費税,0),"" ) ) ) ) ) ) ) ) ) ) | W14: =IF( AND($P14=ストレージ一般解析Quota設定のみ,$Q14<=30),0,IF( AND($P14=ストレージ一般解析Quota設定のみ,$Q14>30),ROUNDDOWN(ROUNDDOWN(ROUNDUP($Q14/10,0)*ストレージ一般解析Quota設定のみ単価*(T14/年間日数),0)*消費税,0),IF( AND($P14=ストレージ個人ゲノムQuota設定のみ),ROUNDDOWN(ROUNDDOWN(ROUNDUP($Q14/10,0)*ストレージ個人ゲノムQuota設定のみ単価*(T14/年間日数),0)*消費税,0),IF( $D14=CPU1_,ROUNDDOWN(ROUNDDOWN(($Q14*CPU3単価*T14/30),0)*消費税,0),IF( $D14=CPU2_,ROUNDDOWN(ROUNDDOWN(($Q14*CPU4単価*T14/30),0)*消費税,0),IF( $D14=Mem1_,ROUNDDOWN(ROUNDDOWN(($Q14*Mem1単価*T14/30),0)*消費税,0),IF( $D14=Mem2_,ROUNDDOWN(ROUNDDOWN(($Q14*Mem2単価*T14/30),0)*消費税,0),IF( $D14=Acc1_,ROUNDDOWN(ROUNDDOWN(($Q14*Acc1単価*T14/30),0)*消費税,0),IF( $D14=Acc2_,ROUNDDOWN(ROUNDDOWN(($Q14*Acc2単価*T14/30),0)*消費税,0),IF( $D14=Acc3_,ROUNDDOWN(ROUNDDOWN(($Q14*Acc3単価*T14/30),0)*消費税,0),"" ) ) ) ) ) ) ) ) ) )
O15: =IF( AND(SUM(E15:N15)>0,OR(C15=Sheet1!$A$1,C15=Sheet1!$A$2)), CONCATENATE(SUM(E15:N15),"TB"), IF( AND(SUM(E15:N15)>0,OR(C15=Sheet1!$A$6,C15=Sheet1!$A$3,C15=Sheet1!$A$7,C15=Sheet1!$A$4),D15=Sheet1!$B$31), CONCATENATE(SUM(E15:N15),"台"), IF( AND( SUM(E15:N15)>0, OR(C15=Sheet1!$A$6,C15=Sheet1!$A$3,C15=Sheet1!$A$7,C15=Sheet1!$A$4,C15=Sheet1!$A$5), OR(D15=Sheet1!$B$25,D15=Sheet1!$B$26,D15=Sheet1!$B$27,D15=Sheet1!$B$28,D15=Sheet1!$B$29,D15=Sheet1!$B$30) ), CONCATENATE(SUM(E15:N15),"単位"), "" ) ) ) | P15: =C15&D15 | Q15: =SUM(E15:N15) -> 0 | R15: =IF(AND($A15<=DATE(年,4,1),$B15>=DATE(年,7,31)),DATEDIF(DATE(年,4,1),DATE(年,7,31),"d")+1,IF(AND($A15>DATE(年,4,1),$A15<=DATE(年,7,31),$B15>=DATE(年,7,31)),DATEDIF($A15,DATE(年,7,31),"d")+1,IF(AND($A15<=DATE(年,4,1),$B15>=DATE(年,4,1),$B15<=DATE(年,7,31)),DATEDIF(DATE(年,4,1),$B15,"d")+1,IF(AND($A15>=DATE(年,4,1),$A15<=DATE(年,7,31),$B15>=DATE(年,4,1),$B15<=DATE(年,7,31)),DATEDIF(A15,B15,"d")+1,0)))) -> 0 | S15: =IF(AND($A15<=DATE(年,8,1),$B15>=DATE(年,11,30)),DATEDIF(DATE(年,8,1),DATE(年,11,30),"d")+1,IF(AND($A15>DATE(年,8,1),$A15<=DATE(年,11,30),$B15>=DATE(年,11,30)),DATEDIF($A15,DATE(年,11,30),"d")+1,IF(AND($A15<=DATE(年,8,1),$B15>=DATE(年,8,1),$B15<=DATE(年,11,30)),DATEDIF(DATE(年,8,1),$B15,"d")+1,IF(AND($A15>=DATE(年,8,1),$A15<=DATE(年,11,30),$B15>=DATE(年,8,1),$B15<=DATE(年,11,30)),DATEDIF($A15,$B15,"d")+1,0)))) -> 0 | T15: =IF(AND($A15<=DATE(年,12,1),$B15>=DATE(年+1,3,31)),DATEDIF(DATE(年,12,1),DATE(年+1,3,31),"d")+1,IF(AND($A15>DATE(年,12,1),$A15<=DATE(年+1,3,31),$B15>=DATE(年+1,3,31)),DATEDIF($A15,DATE(年+1,3,31),"d")+1,IF(AND($A15<=DATE(年,12,1),$B15>=DATE(年,12,1),$B15<=DATE(年+1,3,31)),DATEDIF(DATE(年,12,1),$B15,"d")+1,IF(AND(A15>=DATE(年,12,1),$A15<=DATE(年+1,3,31),$B15>=DATE(年,12,1),$B15<=DATE(年+1,3,31)),DATEDIF($A15,$B15,"d")+1,0)))) -> 0 | U15: =IF( AND($P15=ストレージ一般解析Quota設定のみ,$Q15<=30),0,IF( AND($P15=ストレージ一般解析Quota設定のみ,$Q15>30),ROUNDDOWN(ROUNDDOWN(ROUNDUP($Q15/10,0)*ストレージ一般解析Quota設定のみ単価*(R15/年間日数),0)*消費税,0),IF( AND($P15=ストレージ個人ゲノムQuota設定のみ),ROUNDDOWN(ROUNDDOWN(ROUNDUP($Q15/10,0)*ストレージ個人ゲノムQuota設定のみ単価*(R15/年間日数),0)*消費税,0),IF( $D15=CPU1_,ROUNDDOWN(ROUNDDOWN(($Q15*CPU4単価*R15/30),0)*消費税,0),IF( $D15=CPU2_,ROUNDDOWN(ROUNDDOWN(($Q15*CPU5単価*R15/30),0)*消費税,0),IF( $D15=Mem1_,ROUNDDOWN(ROUNDDOWN(($Q15*Mem1単価*R15/30),0)*消費税,0),IF( $D15=Mem2_,ROUNDDOWN(ROUNDDOWN(($Q15*Mem2単価*R15/30),0)*消費税,0),IF( $D15=Acc1_,ROUNDDOWN(ROUNDDOWN(($Q15*Acc1単価*R15/30),0)*消費税,0),IF( $D15=Acc2_,ROUNDDOWN(ROUNDDOWN(($Q15*Acc2単価*R15/30),0)*消費税,0),IF( $D15=Acc3_,ROUNDDOWN(ROUNDDOWN(($Q15*Acc3単価*R15/30),0)*消費税,0),"" ) ) ) ) ) ) ) ) ) ) | V15: =IF( AND($P15=ストレージ一般解析Quota設定のみ,$Q15<=30),0,IF( AND($P15=ストレージ一般解析Quota設定のみ,$Q15>30),ROUNDDOWN(ROUNDDOWN(ROUNDUP($Q15/10,0)*ストレージ一般解析Quota設定のみ単価*(S15/年間日数),0)*消費税,0),IF( AND($P15=ストレージ個人ゲノムQuota設定のみ),ROUNDDOWN(ROUNDDOWN(ROUNDUP($Q15/10,0)*ストレージ個人ゲノムQuota設定のみ単価*(S15/年間日数),0)*消費税,0),IF( $D15=CPU1_,ROUNDDOWN(ROUNDDOWN(($Q15*CPU4単価*S15/30),0)*消費税,0),IF( $D15=CPU2_,ROUNDDOWN(ROUNDDOWN(($Q15*CPU5単価*S15/30),0)*消費税,0),IF( $D15=Mem1_,ROUNDDOWN(ROUNDDOWN(($Q15*Mem1単価*S15/30),0)*消費税,0),IF( $D15=Mem2_,ROUNDDOWN(ROUNDDOWN(($Q15*Mem2単価*S15/30),0)*消費税,0),IF( $D15=Acc1_,ROUNDDOWN(ROUNDDOWN(($Q15*Acc1単価*S15/30),0)*消費税,0),IF( $D15=Acc2_,ROUNDDOWN(ROUNDDOWN(($Q15*Acc2単価*S15/30),0)*消費税,0),IF( $D15=Acc3_,ROUNDDOWN(ROUNDDOWN(($Q15*Acc3単価*S15/30),0)*消費税,0),"" ) ) ) ) ) ) ) ) ) ) | W15: =IF( AND($P15=ストレージ一般解析Quota設定のみ,$Q15<=30),0,IF( AND($P15=ストレージ一般解析Quota設定のみ,$Q15>30),ROUNDDOWN(ROUNDDOWN(ROUNDUP($Q15/10,0)*ストレージ一般解析Quota設定のみ単価*(T15/年間日数),0)*消費税,0),IF( AND($P15=ストレージ個人ゲノムQuota設定のみ),ROUNDDOWN(ROUNDDOWN(ROUNDUP($Q15/10,0)*ストレージ個人ゲノムQuota設定のみ単価*(T15/年間日数),0)*消費税,0),IF( $D15=CPU1_,ROUNDDOWN(ROUNDDOWN(($Q15*CPU4単価*T15/30),0)*消費税,0),IF( $D15=CPU2_,ROUNDDOWN(ROUNDDOWN(($Q15*CPU5単価*T15/30),0)*消費税,0),IF( $D15=Mem1_,ROUNDDOWN(ROUNDDOWN(($Q15*Mem1単価*T15/30),0)*消費税,0),IF( $D15=Mem2_,ROUNDDOWN(ROUNDDOWN(($Q15*Mem2単価*T15/30),0)*消費税,0),IF( $D15=Acc1_,ROUNDDOWN(ROUNDDOWN(($Q15*Acc1単価*T15/30),0)*消費税,0),IF( $D15=Acc2_,ROUNDDOWN(ROUNDDOWN(($Q15*Acc2単価*T15/30),0)*消費税,0),IF( $D15=Acc3_,ROUNDDOWN(ROUNDDOWN(($Q15*Acc3単価*T15/30),0)*消費税,0),"" ) ) ) ) ) ) ) ) ) )
O16: =IF( AND(SUM(E16:N16)>0,OR(C16=Sheet1!$A$1,C16=Sheet1!$A$2)), CONCATENATE(SUM(E16:N16),"TB"), IF( AND(SUM(E16:N16)>0,OR(C16=Sheet1!$A$6,C16=Sheet1!$A$3,C16=Sheet1!$A$7,C16=Sheet1!$A$4),D16=Sheet1!$B$31), CONCATENATE(SUM(E16:N16),"台"), IF( AND( SUM(E16:N16)>0, OR(C16=Sheet1!$A$6,C16=Sheet1!$A$3,C16=Sheet1!$A$7,C16=Sheet1!$A$4,C16=Sheet1!$A$5), OR(D16=Sheet1!$B$25,D16=Sheet1!$B$26,D16=Sheet1!$B$27,D16=Sheet1!$B$28,D16=Sheet1!$B$29,D16=Sheet1!$B$30) ), CONCATENATE(SUM(E16:N16),"単位"), "" ) ) ) | P16: =C16&D16 | Q16: =SUM(E16:N16) -> 0 | R16: =IF(AND($A16<=DATE(年,4,1),$B16>=DATE(年,7,31)),DATEDIF(DATE(年,4,1),DATE(年,7,31),"d")+1,IF(AND($A16>DATE(年,4,1),$A16<=DATE(年,7,31),$B16>=DATE(年,7,31)),DATEDIF($A16,DATE(年,7,31),"d")+1,IF(AND($A16<=DATE(年,4,1),$B16>=DATE(年,4,1),$B16<=DATE(年,7,31)),DATEDIF(DATE(年,4,1),$B16,"d")+1,IF(AND($A16>=DATE(年,4,1),$A16<=DATE(年,7,31),$B16>=DATE(年,4,1),$B16<=DATE(年,7,31)),DATEDIF(A16,B16,"d")+1,0)))) -> 0 | S16: =IF(AND($A16<=DATE(年,8,1),$B16>=DATE(年,11,30)),DATEDIF(DATE(年,8,1),DATE(年,11,30),"d")+1,IF(AND($A16>DATE(年,8,1),$A16<=DATE(年,11,30),$B16>=DATE(年,11,30)),DATEDIF($A16,DATE(年,11,30),"d")+1,IF(AND($A16<=DATE(年,8,1),$B16>=DATE(年,8,1),$B16<=DATE(年,11,30)),DATEDIF(DATE(年,8,1),$B16,"d")+1,IF(AND($A16>=DATE(年,8,1),$A16<=DATE(年,11,30),$B16>=DATE(年,8,1),$B16<=DATE(年,11,30)),DATEDIF($A16,$B16,"d")+1,0)))) -> 0 | T16: =IF(AND($A16<=DATE(年,12,1),$B16>=DATE(年+1,3,31)),DATEDIF(DATE(年,12,1),DATE(年+1,3,31),"d")+1,IF(AND($A16>DATE(年,12,1),$A16<=DATE(年+1,3,31),$B16>=DATE(年+1,3,31)),DATEDIF($A16,DATE(年+1,3,31),"d")+1,IF(AND($A16<=DATE(年,12,1),$B16>=DATE(年,12,1),$B16<=DATE(年+1,3,31)),DATEDIF(DATE(年,12,1),$B16,"d")+1,IF(AND(A16>=DATE(年,12,1),$A16<=DATE(年+1,3,31),$B16>=DATE(年,12,1),$B16<=DATE(年+1,3,31)),DATEDIF($A16,$B16,"d")+1,0)))) -> 0 | U16: =IF( AND($P16=ストレージ一般解析Quota設定のみ,$Q16<=30),0,IF( AND($P16=ストレージ一般解析Quota設定のみ,$Q16>30),ROUNDDOWN(ROUNDDOWN(ROUNDUP($Q16/10,0)*ストレージ一般解析Quota設定のみ単価*(R16/年間日数),0)*消費税,0),IF( AND($P16=ストレージ個人ゲノムQuota設定のみ),ROUNDDOWN(ROUNDDOWN(ROUNDUP($Q16/10,0)*ストレージ個人ゲノムQuota設定のみ単価*(R16/年間日数),0)*消費税,0),IF( $D16=CPU1_,ROUNDDOWN(ROUNDDOWN(($Q16*CPU5単価*R16/30),0)*消費税,0),IF( $D16=CPU2_,ROUNDDOWN(ROUNDDOWN(($Q16*CPU6単価*R16/30),0)*消費税,0),IF( $D16=Mem1_,ROUNDDOWN(ROUNDDOWN(($Q16*Mem1単価*R16/30),0)*消費税,0),IF( $D16=Mem2_,ROUNDDOWN(ROUNDDOWN(($Q16*Mem2単価*R16/30),0)*消費税,0),IF( $D16=Acc1_,ROUNDDOWN(ROUNDDOWN(($Q16*Acc1単価*R16/30),0)*消費税,0),IF( $D16=Acc2_,ROUNDDOWN(ROUNDDOWN(($Q16*Acc2単価*R16/30),0)*消費税,0),IF( $D16=Acc3_,ROUNDDOWN(ROUNDDOWN(($Q16*Acc3単価*R16/30),0)*消費税,0),"" ) ) ) ) ) ) ) ) ) ) | V16: =IF( AND($P16=ストレージ一般解析Quota設定のみ,$Q16<=30),0,IF( AND($P16=ストレージ一般解析Quota設定のみ,$Q16>30),ROUNDDOWN(ROUNDDOWN(ROUNDUP($Q16/10,0)*ストレージ一般解析Quota設定のみ単価*(S16/年間日数),0)*消費税,0),IF( AND($P16=ストレージ個人ゲノムQuota設定のみ),ROUNDDOWN(ROUNDDOWN(ROUNDUP($Q16/10,0)*ストレージ個人ゲノムQuota設定のみ単価*(S16/年間日数),0)*消費税,0),IF( $D16=CPU1_,ROUNDDOWN(ROUNDDOWN(($Q16*CPU5単価*S16/30),0)*消費税,0),IF( $D16=CPU2_,ROUNDDOWN(ROUNDDOWN(($Q16*CPU6単価*S16/30),0)*消費税,0),IF( $D16=Mem1_,ROUNDDOWN(ROUNDDOWN(($Q16*Mem1単価*S16/30),0)*消費税,0),IF( $D16=Mem2_,ROUNDDOWN(ROUNDDOWN(($Q16*Mem2単価*S16/30),0)*消費税,0),IF( $D16=Acc1_,ROUNDDOWN(ROUNDDOWN(($Q16*Acc1単価*S16/30),0)*消費税,0),IF( $D16=Acc2_,ROUNDDOWN(ROUNDDOWN(($Q16*Acc2単価*S16/30),0)*消費税,0),IF( $D16=Acc3_,ROUNDDOWN(ROUNDDOWN(($Q16*Acc3単価*S16/30),0)*消費税,0),"" ) ) ) ) ) ) ) ) ) ) | W16: =IF( AND($P16=ストレージ一般解析Quota設定のみ,$Q16<=30),0,IF( AND($P16=ストレージ一般解析Quota設定のみ,$Q16>30),ROUNDDOWN(ROUNDDOWN(ROUNDUP($Q16/10,0)*ストレージ一般解析Quota設定のみ単価*(T16/年間日数),0)*消費税,0),IF( AND($P16=ストレージ個人ゲノムQuota設定のみ),ROUNDDOWN(ROUNDDOWN(ROUNDUP($Q16/10,0)*ストレージ個人ゲノムQuota設定のみ単価*(T16/年間日数),0)*消費税,0),IF( $D16=CPU1_,ROUNDDOWN(ROUNDDOWN(($Q16*CPU5単価*T16/30),0)*消費税,0),IF( $D16=CPU2_,ROUNDDOWN(ROUNDDOWN(($Q16*CPU6単価*T16/30),0)*消費税,0),IF( $D16=Mem1_,ROUNDDOWN(ROUNDDOWN(($Q16*Mem1単価*T16/30),0)*消費税,0),IF( $D16=Mem2_,ROUNDDOWN(ROUNDDOWN(($Q16*Mem2単価*T16/30),0)*消費税,0),IF( $D16=Acc1_,ROUNDDOWN(ROUNDDOWN(($Q16*Acc1単価*T16/30),0)*消費税,0),IF( $D16=Acc2_,ROUNDDOWN(ROUNDDOWN(($Q16*Acc2単価*T16/30),0)*消費税,0),IF( $D16=Acc3_,ROUNDDOWN(ROUNDDOWN(($Q16*Acc3単価*T16/30),0)*消費税,0),"" ) ) ) ) ) ) ) ) ) )
O17: =IF( AND(SUM(E17:N17)>0,OR(C17=Sheet1!$A$1,C17=Sheet1!$A$2)), CONCATENATE(SUM(E17:N17),"TB"), IF( AND(SUM(E17:N17)>0,OR(C17=Sheet1!$A$6,C17=Sheet1!$A$3,C17=Sheet1!$A$7,C17=Sheet1!$A$4),D17=Sheet1!$B$31), CONCATENATE(SUM(E17:N17),"台"), IF( AND( SUM(E17:N17)>0, OR(C17=Sheet1!$A$6,C17=Sheet1!$A$3,C17=Sheet1!$A$7,C17=Sheet1!$A$4,C17=Sheet1!$A$5), OR(D17=Sheet1!$B$25,D17=Sheet1!$B$26,D17=Sheet1!$B$27,D17=Sheet1!$B$28,D17=Sheet1!$B$29,D17=Sheet1!$B$30) ), CONCATENATE(SUM(E17:N17),"単位"), "" ) ) ) | P17: =C17&D17 | Q17: =SUM(E17:N17) -> 0 | R17: =IF(AND($A17<=DATE(年,4,1),$B17>=DATE(年,7,31)),DATEDIF(DATE(年,4,1),DATE(年,7,31),"d")+1,IF(AND($A17>DATE(年,4,1),$A17<=DATE(年,7,31),$B17>=DATE(年,7,31)),DATEDIF($A17,DATE(年,7,31),"d")+1,IF(AND($A17<=DATE(年,4,1),$B17>=DATE(年,4,1),$B17<=DATE(年,7,31)),DATEDIF(DATE(年,4,1),$B17,"d")+1,IF(AND($A17>=DATE(年,4,1),$A17<=DATE(年,7,31),$B17>=DATE(年,4,1),$B17<=DATE(年,7,31)),DATEDIF(A17,B17,"d")+1,0)))) -> 0 | S17: =IF(AND($A17<=DATE(年,8,1),$B17>=DATE(年,11,30)),DATEDIF(DATE(年,8,1),DATE(年,11,30),"d")+1,IF(AND($A17>DATE(年,8,1),$A17<=DATE(年,11,30),$B17>=DATE(年,11,30)),DATEDIF($A17,DATE(年,11,30),"d")+1,IF(AND($A17<=DATE(年,8,1),$B17>=DATE(年,8,1),$B17<=DATE(年,11,30)),DATEDIF(DATE(年,8,1),$B17,"d")+1,IF(AND($A17>=DATE(年,8,1),$A17<=DATE(年,11,30),$B17>=DATE(年,8,1),$B17<=DATE(年,11,30)),DATEDIF($A17,$B17,"d")+1,0)))) -> 0 | T17: =IF(AND($A17<=DATE(年,12,1),$B17>=DATE(年+1,3,31)),DATEDIF(DATE(年,12,1),DATE(年+1,3,31),"d")+1,IF(AND($A17>DATE(年,12,1),$A17<=DATE(年+1,3,31),$B17>=DATE(年+1,3,31)),DATEDIF($A17,DATE(年+1,3,31),"d")+1,IF(AND($A17<=DATE(年,12,1),$B17>=DATE(年,12,1),$B17<=DATE(年+1,3,31)),DATEDIF(DATE(年,12,1),$B17,"d")+1,IF(AND(A17>=DATE(年,12,1),$A17<=DATE(年+1,3,31),$B17>=DATE(年,12,1),$B17<=DATE(年+1,3,31)),DATEDIF($A17,$B17,"d")+1,0)))) -> 0 | U17: =IF( AND($P17=ストレージ一般解析Quota設定のみ,$Q17<=30),0,IF( AND($P17=ストレージ一般解析Quota設定のみ,$Q17>30),ROUNDDOWN(ROUNDDOWN(ROUNDUP($Q17/10,0)*ストレージ一般解析Quota設定のみ単価*(R17/年間日数),0)*消費税,0),IF( AND($P17=ストレージ個人ゲノムQuota設定のみ),ROUNDDOWN(ROUNDDOWN(ROUNDUP($Q17/10,0)*ストレージ個人ゲノムQuota設定のみ単価*(R17/年間日数),0)*消費税,0),IF( $D17=CPU1_,ROUNDDOWN(ROUNDDOWN(($Q17*CPU6単価*R17/30),0)*消費税,0),IF( $D17=CPU2_,ROUNDDOWN(ROUNDDOWN(($Q17*CPU7単価*R17/30),0)*消費税,0),IF( $D17=Mem1_,ROUNDDOWN(ROUNDDOWN(($Q17*Mem1単価*R17/30),0)*消費税,0),IF( $D17=Mem2_,ROUNDDOWN(ROUNDDOWN(($Q17*Mem2単価*R17/30),0)*消費税,0),IF( $D17=Acc1_,ROUNDDOWN(ROUNDDOWN(($Q17*Acc1単価*R17/30),0)*消費税,0),IF( $D17=Acc2_,ROUNDDOWN(ROUNDDOWN(($Q17*Acc2単価*R17/30),0)*消費税,0),IF( $D17=Acc3_,ROUNDDOWN(ROUNDDOWN(($Q17*Acc3単価*R17/30),0)*消費税,0),"" ) ) ) ) ) ) ) ) ) ) | V17: =IF( AND($P17=ストレージ一般解析Quota設定のみ,$Q17<=30),0,IF( AND($P17=ストレージ一般解析Quota設定のみ,$Q17>30),ROUNDDOWN(ROUNDDOWN(ROUNDUP($Q17/10,0)*ストレージ一般解析Quota設定のみ単価*(S17/年間日数),0)*消費税,0),IF( AND($P17=ストレージ個人ゲノムQuota設定のみ),ROUNDDOWN(ROUNDDOWN(ROUNDUP($Q17/10,0)*ストレージ個人ゲノムQuota設定のみ単価*(S17/年間日数),0)*消費税,0),IF( $D17=CPU1_,ROUNDDOWN(ROUNDDOWN(($Q17*CPU6単価*S17/30),0)*消費税,0),IF( $D17=CPU2_,ROUNDDOWN(ROUNDDOWN(($Q17*CPU7単価*S17/30),0)*消費税,0),IF( $D17=Mem1_,ROUNDDOWN(ROUNDDOWN(($Q17*Mem1単価*S17/30),0)*消費税,0),IF( $D17=Mem2_,ROUNDDOWN(ROUNDDOWN(($Q17*Mem2単価*S17/30),0)*消費税,0),IF( $D17=Acc1_,ROUNDDOWN(ROUNDDOWN(($Q17*Acc1単価*S17/30),0)*消費税,0),IF( $D17=Acc2_,ROUNDDOWN(ROUNDDOWN(($Q17*Acc2単価*S17/30),0)*消費税,0),IF( $D17=Acc3_,ROUNDDOWN(ROUNDDOWN(($Q17*Acc3単価*S17/30),0)*消費税,0),"" ) ) ) ) ) ) ) ) ) ) | W17: =IF( AND($P17=ストレージ一般解析Quota設定のみ,$Q17<=30),0,IF( AND($P17=ストレージ一般解析Quota設定のみ,$Q17>30),ROUNDDOWN(ROUNDDOWN(ROUNDUP($Q17/10,0)*ストレージ一般解析Quota設定のみ単価*(T17/年間日数),0)*消費税,0),IF( AND($P17=ストレージ個人ゲノムQuota設定のみ),ROUNDDOWN(ROUNDDOWN(ROUNDUP($Q17/10,0)*ストレージ個人ゲノムQuota設定のみ単価*(T17/年間日数),0)*消費税,0),IF( $D17=CPU1_,ROUNDDOWN(ROUNDDOWN(($Q17*CPU6単価*T17/30),0)*消費税,0),IF( $D17=CPU2_,ROUNDDOWN(ROUNDDOWN(($Q17*CPU7単価*T17/30),0)*消費税,0),IF( $D17=Mem1_,ROUNDDOWN(ROUNDDOWN(($Q17*Mem1単価*T17/30),0)*消費税,0),IF( $D17=Mem2_,ROUNDDOWN(ROUNDDOWN(($Q17*Mem2単価*T17/30),0)*消費税,0),IF( $D17=Acc1_,ROUNDDOWN(ROUNDDOWN(($Q17*Acc1単価*T17/30),0)*消費税,0),IF( $D17=Acc2_,ROUNDDOWN(ROUNDDOWN(($Q17*Acc2単価*T17/30),0)*消費税,0),IF( $D17=Acc3_,ROUNDDOWN(ROUNDDOWN(($Q17*Acc3単価*T17/30),0)*消費税,0),"" ) ) ) ) ) ) ) ) ) )
O18: =IF( AND(SUM(E18:N18)>0,OR(C18=Sheet1!$A$1,C18=Sheet1!$A$2)), CONCATENATE(SUM(E18:N18),"TB"), IF( AND(SUM(E18:N18)>0,OR(C18=Sheet1!$A$6,C18=Sheet1!$A$3,C18=Sheet1!$A$7,C18=Sheet1!$A$4),D18=Sheet1!$B$31), CONCATENATE(SUM(E18:N18),"台"), IF( AND( SUM(E18:N18)>0, OR(C18=Sheet1!$A$6,C18=Sheet1!$A$3,C18=Sheet1!$A$7,C18=Sheet1!$A$4,C18=Sheet1!$A$5), OR(D18=Sheet1!$B$25,D18=Sheet1!$B$26,D18=Sheet1!$B$27,D18=Sheet1!$B$28,D18=Sheet1!$B$29,D18=Sheet1!$B$30) ), CONCATENATE(SUM(E18:N18),"単位"), "" ) ) ) | P18: =C18&D18 | Q18: =SUM(E18:N18) -> 0 | R18: =IF(AND($A18<=DATE(年,4,1),$B18>=DATE(年,7,31)),DATEDIF(DATE(年,4,1),DATE(年,7,31),"d")+1,IF(AND($A18>DATE(年,4,1),$A18<=DATE(年,7,31),$B18>=DATE(年,7,31)),DATEDIF($A18,DATE(年,7,31),"d")+1,IF(AND($A18<=DATE(年,4,1),$B18>=DATE(年,4,1),$B18<=DATE(年,7,31)),DATEDIF(DATE(年,4,1),$B18,"d")+1,IF(AND($A18>=DATE(年,4,1),$A18<=DATE(年,7,31),$B18>=DATE(年,4,1),$B18<=DATE(年,7,31)),DATEDIF(A18,B18,"d")+1,0)))) -> 0 | S18: =IF(AND($A18<=DATE(年,8,1),$B18>=DATE(年,11,30)),DATEDIF(DATE(年,8,1),DATE(年,11,30),"d")+1,IF(AND($A18>DATE(年,8,1),$A18<=DATE(年,11,30),$B18>=DATE(年,11,30)),DATEDIF($A18,DATE(年,11,30),"d")+1,IF(AND($A18<=DATE(年,8,1),$B18>=DATE(年,8,1),$B18<=DATE(年,11,30)),DATEDIF(DATE(年,8,1),$B18,"d")+1,IF(AND($A18>=DATE(年,8,1),$A18<=DATE(年,11,30),$B18>=DATE(年,8,1),$B18<=DATE(年,11,30)),DATEDIF($A18,$B18,"d")+1,0)))) -> 0 | T18: =IF(AND($A18<=DATE(年,12,1),$B18>=DATE(年+1,3,31)),DATEDIF(DATE(年,12,1),DATE(年+1,3,31),"d")+1,IF(AND($A18>DATE(年,12,1),$A18<=DATE(年+1,3,31),$B18>=DATE(年+1,3,31)),DATEDIF($A18,DATE(年+1,3,31),"d")+1,IF(AND($A18<=DATE(年,12,1),$B18>=DATE(年,12,1),$B18<=DATE(年+1,3,31)),DATEDIF(DATE(年,12,1),$B18,"d")+1,IF(AND(A18>=DATE(年,12,1),$A18<=DATE(年+1,3,31),$B18>=DATE(年,12,1),$B18<=DATE(年+1,3,31)),DATEDIF($A18,$B18,"d")+1,0)))) -> 0 | U18: =IF( AND($P18=ストレージ一般解析Quota設定のみ,$Q18<=30),0,IF( AND($P18=ストレージ一般解析Quota設定のみ,$Q18>30),ROUNDDOWN(ROUNDDOWN(ROUNDUP($Q18/10,0)*ストレージ一般解析Quota設定のみ単価*(R18/年間日数),0)*消費税,0),IF( AND($P18=ストレージ個人ゲノムQuota設定のみ),ROUNDDOWN(ROUNDDOWN(ROUNDUP($Q18/10,0)*ストレージ個人ゲノムQuota設定のみ単価*(R18/年間日数),0)*消費税,0),IF( $D18=CPU1_,ROUNDDOWN(ROUNDDOWN(($Q18*CPU7単価*R18/30),0)*消費税,0),IF( $D18=CPU2_,ROUNDDOWN(ROUNDDOWN(($Q18*CPU8単価*R18/30),0)*消費税,0),IF( $D18=Mem1_,ROUNDDOWN(ROUNDDOWN(($Q18*Mem1単価*R18/30),0)*消費税,0),IF( $D18=Mem2_,ROUNDDOWN(ROUNDDOWN(($Q18*Mem2単価*R18/30),0)*消費税,0),IF( $D18=Acc1_,ROUNDDOWN(ROUNDDOWN(($Q18*Acc1単価*R18/30),0)*消費税,0),IF( $D18=Acc2_,ROUNDDOWN(ROUNDDOWN(($Q18*Acc2単価*R18/30),0)*消費税,0),IF( $D18=Acc3_,ROUNDDOWN(ROUNDDOWN(($Q18*Acc3単価*R18/30),0)*消費税,0),"" ) ) ) ) ) ) ) ) ) ) | V18: =IF( AND($P18=ストレージ一般解析Quota設定のみ,$Q18<=30),0,IF( AND($P18=ストレージ一般解析Quota設定のみ,$Q18>30),ROUNDDOWN(ROUNDDOWN(ROUNDUP($Q18/10,0)*ストレージ一般解析Quota設定のみ単価*(S18/年間日数),0)*消費税,0),IF( AND($P18=ストレージ個人ゲノムQuota設定のみ),ROUNDDOWN(ROUNDDOWN(ROUNDUP($Q18/10,0)*ストレージ個人ゲノムQuota設定のみ単価*(S18/年間日数),0)*消費税,0),IF( $D18=CPU1_,ROUNDDOWN(ROUNDDOWN(($Q18*CPU7単価*S18/30),0)*消費税,0),IF( $D18=CPU2_,ROUNDDOWN(ROUNDDOWN(($Q18*CPU8単価*S18/30),0)*消費税,0),IF( $D18=Mem1_,ROUNDDOWN(ROUNDDOWN(($Q18*Mem1単価*S18/30),0)*消費税,0),IF( $D18=Mem2_,ROUNDDOWN(ROUNDDOWN(($Q18*Mem2単価*S18/30),0)*消費税,0),IF( $D18=Acc1_,ROUNDDOWN(ROUNDDOWN(($Q18*Acc1単価*S18/30),0)*消費税,0),IF( $D18=Acc2_,ROUNDDOWN(ROUNDDOWN(($Q18*Acc2単価*S18/30),0)*消費税,0),IF( $D18=Acc3_,ROUNDDOWN(ROUNDDOWN(($Q18*Acc3単価*S18/30),0)*消費税,0),"" ) ) ) ) ) ) ) ) ) ) | W18: =IF( AND($P18=ストレージ一般解析Quota設定のみ,$Q18<=30),0,IF( AND($P18=ストレージ一般解析Quota設定のみ,$Q18>30),ROUNDDOWN(ROUNDDOWN(ROUNDUP($Q18/10,0)*ストレージ一般解析Quota設定のみ単価*(T18/年間日数),0)*消費税,0),IF( AND($P18=ストレージ個人ゲノムQuota設定のみ),ROUNDDOWN(ROUNDDOWN(ROUNDUP($Q18/10,0)*ストレージ個人ゲノムQuota設定のみ単価*(T18/年間日数),0)*消費税,0),IF( $D18=CPU1_,ROUNDDOWN(ROUNDDOWN(($Q18*CPU7単価*T18/30),0)*消費税,0),IF( $D18=CPU2_,ROUNDDOWN(ROUNDDOWN(($Q18*CPU8単価*T18/30),0)*消費税,0),IF( $D18=Mem1_,ROUNDDOWN(ROUNDDOWN(($Q18*Mem1単価*T18/30),0)*消費税,0),IF( $D18=Mem2_,ROUNDDOWN(ROUNDDOWN(($Q18*Mem2単価*T18/30),0)*消費税,0),IF( $D18=Acc1_,ROUNDDOWN(ROUNDDOWN(($Q18*Acc1単価*T18/30),0)*消費税,0),IF( $D18=Acc2_,ROUNDDOWN(ROUNDDOWN(($Q18*Acc2単価*T18/30),0)*消費税,0),IF( $D18=Acc3_,ROUNDDOWN(ROUNDDOWN(($Q18*Acc3単価*T18/30),0)*消費税,0),"" ) ) ) ) ) ) ) ) ) )
O19: =IF( AND(SUM(E19:N19)>0,OR(C19=Sheet1!$A$1,C19=Sheet1!$A$2)), CONCATENATE(SUM(E19:N19),"TB"), IF( AND(SUM(E19:N19)>0,OR(C19=Sheet1!$A$6,C19=Sheet1!$A$3,C19=Sheet1!$A$7,C19=Sheet1!$A$4),D19=Sheet1!$B$31), CONCATENATE(SUM(E19:N19),"台"), IF( AND( SUM(E19:N19)>0, OR(C19=Sheet1!$A$6,C19=Sheet1!$A$3,C19=Sheet1!$A$7,C19=Sheet1!$A$4,C19=Sheet1!$A$5), OR(D19=Sheet1!$B$25,D19=Sheet1!$B$26,D19=Sheet1!$B$27,D19=Sheet1!$B$28,D19=Sheet1!$B$29,D19=Sheet1!$B$30) ), CONCATENATE(SUM(E19:N19),"単位"), "" ) ) ) | P19: =C19&D19 | Q19: =SUM(E19:N19) -> 0 | R19: =IF(AND($A19<=DATE(年,4,1),$B19>=DATE(年,7,31)),DATEDIF(DATE(年,4,1),DATE(年,7,31),"d")+1,IF(AND($A19>DATE(年,4,1),$A19<=DATE(年,7,31),$B19>=DATE(年,7,31)),DATEDIF($A19,DATE(年,7,31),"d")+1,IF(AND($A19<=DATE(年,4,1),$B19>=DATE(年,4,1),$B19<=DATE(年,7,31)),DATEDIF(DATE(年,4,1),$B19,"d")+1,IF(AND($A19>=DATE(年,4,1),$A19<=DATE(年,7,31),$B19>=DATE(年,4,1),$B19<=DATE(年,7,31)),DATEDIF(A19,B19,"d")+1,0)))) -> 0 | S19: =IF(AND($A19<=DATE(年,8,1),$B19>=DATE(年,11,30)),DATEDIF(DATE(年,8,1),DATE(年,11,30),"d")+1,IF(AND($A19>DATE(年,8,1),$A19<=DATE(年,11,30),$B19>=DATE(年,11,30)),DATEDIF($A19,DATE(年,11,30),"d")+1,IF(AND($A19<=DATE(年,8,1),$B19>=DATE(年,8,1),$B19<=DATE(年,11,30)),DATEDIF(DATE(年,8,1),$B19,"d")+1,IF(AND($A19>=DATE(年,8,1),$A19<=DATE(年,11,30),$B19>=DATE(年,8,1),$B19<=DATE(年,11,30)),DATEDIF($A19,$B19,"d")+1,0)))) -> 0 | T19: =IF(AND($A19<=DATE(年,12,1),$B19>=DATE(年+1,3,31)),DATEDIF(DATE(年,12,1),DATE(年+1,3,31),"d")+1,IF(AND($A19>DATE(年,12,1),$A19<=DATE(年+1,3,31),$B19>=DATE(年+1,3,31)),DATEDIF($A19,DATE(年+1,3,31),"d")+1,IF(AND($A19<=DATE(年,12,1),$B19>=DATE(年,12,1),$B19<=DATE(年+1,3,31)),DATEDIF(DATE(年,12,1),$B19,"d")+1,IF(AND(A19>=DATE(年,12,1),$A19<=DATE(年+1,3,31),$B19>=DATE(年,12,1),$B19<=DATE(年+1,3,31)),DATEDIF($A19,$B19,"d")+1,0)))) -> 0 | U19: =IF( AND($P19=ストレージ一般解析Quota設定のみ,$Q19<=30),0,IF( AND($P19=ストレージ一般解析Quota設定のみ,$Q19>30),ROUNDDOWN(ROUNDDOWN(ROUNDUP($Q19/10,0)*ストレージ一般解析Quota設定のみ単価*(R19/年間日数),0)*消費税,0),IF( AND($P19=ストレージ個人ゲノムQuota設定のみ),ROUNDDOWN(ROUNDDOWN(ROUNDUP($Q19/10,0)*ストレージ個人ゲノムQuota設定のみ単価*(R19/年間日数),0)*消費税,0),IF( $D19=CPU1_,ROUNDDOWN(ROUNDDOWN(($Q19*CPU8単価*R19/30),0)*消費税,0),IF( $D19=CPU2_,ROUNDDOWN(ROUNDDOWN(($Q19*CPU9単価*R19/30),0)*消費税,0),IF( $D19=Mem1_,ROUNDDOWN(ROUNDDOWN(($Q19*Mem1単価*R19/30),0)*消費税,0),IF( $D19=Mem2_,ROUNDDOWN(ROUNDDOWN(($Q19*Mem2単価*R19/30),0)*消費税,0),IF( $D19=Acc1_,ROUNDDOWN(ROUNDDOWN(($Q19*Acc1単価*R19/30),0)*消費税,0),IF( $D19=Acc2_,ROUNDDOWN(ROUNDDOWN(($Q19*Acc2単価*R19/30),0)*消費税,0),IF( $D19=Acc3_,ROUNDDOWN(ROUNDDOWN(($Q19*Acc3単価*R19/30),0)*消費税,0),"" ) ) ) ) ) ) ) ) ) ) | V19: =IF( AND($P19=ストレージ一般解析Quota設定のみ,$Q19<=30),0,IF( AND($P19=ストレージ一般解析Quota設定のみ,$Q19>30),ROUNDDOWN(ROUNDDOWN(ROUNDUP($Q19/10,0)*ストレージ一般解析Quota設定のみ単価*(S19/年間日数),0)*消費税,0),IF( AND($P19=ストレージ個人ゲノムQuota設定のみ),ROUNDDOWN(ROUNDDOWN(ROUNDUP($Q19/10,0)*ストレージ個人ゲノムQuota設定のみ単価*(S19/年間日数),0)*消費税,0),IF( $D19=CPU1_,ROUNDDOWN(ROUNDDOWN(($Q19*CPU8単価*S19/30),0)*消費税,0),IF( $D19=CPU2_,ROUNDDOWN(ROUNDDOWN(($Q19*CPU9単価*S19/30),0)*消費税,0),IF( $D19=Mem1_,ROUNDDOWN(ROUNDDOWN(($Q19*Mem1単価*S19/30),0)*消費税,0),IF( $D19=Mem2_,ROUNDDOWN(ROUNDDOWN(($Q19*Mem2単価*S19/30),0)*消費税,0),IF( $D19=Acc1_,ROUNDDOWN(ROUNDDOWN(($Q19*Acc1単価*S19/30),0)*消費税,0),IF( $D19=Acc2_,ROUNDDOWN(ROUNDDOWN(($Q19*Acc2単価*S19/30),0)*消費税,0),IF( $D19=Acc3_,ROUNDDOWN(ROUNDDOWN(($Q19*Acc3単価*S19/30),0)*消費税,0),"" ) ) ) ) ) ) ) ) ) ) | W19: =IF( AND($P19=ストレージ一般解析Quota設定のみ,$Q19<=30),0,IF( AND($P19=ストレージ一般解析Quota設定のみ,$Q19>30),ROUNDDOWN(ROUNDDOWN(ROUNDUP($Q19/10,0)*ストレージ一般解析Quota設定のみ単価*(T19/年間日数),0)*消費税,0),IF( AND($P19=ストレージ個人ゲノムQuota設定のみ),ROUNDDOWN(ROUNDDOWN(ROUNDUP($Q19/10,0)*ストレージ個人ゲノムQuota設定のみ単価*(T19/年間日数),0)*消費税,0),IF( $D19=CPU1_,ROUNDDOWN(ROUNDDOWN(($Q19*CPU8単価*T19/30),0)*消費税,0),IF( $D19=CPU2_,ROUNDDOWN(ROUNDDOWN(($Q19*CPU9単価*T19/30),0)*消費税,0),IF( $D19=Mem1_,ROUNDDOWN(ROUNDDOWN(($Q19*Mem1単価*T19/30),0)*消費税,0),IF( $D19=Mem2_,ROUNDDOWN(ROUNDDOWN(($Q19*Mem2単価*T19/30),0)*消費税,0),IF( $D19=Acc1_,ROUNDDOWN(ROUNDDOWN(($Q19*Acc1単価*T19/30),0)*消費税,0),IF( $D19=Acc2_,ROUNDDOWN(ROUNDDOWN(($Q19*Acc2単価*T19/30),0)*消費税,0),IF( $D19=Acc3_,ROUNDDOWN(ROUNDDOWN(($Q19*Acc3単価*T19/30),0)*消費税,0),"" ) ) ) ) ) ) ) ) ) )
O20: =IF( AND(SUM(E20:N20)>0,OR(C20=Sheet1!$A$1,C20=Sheet1!$A$2)), CONCATENATE(SUM(E20:N20),"TB"), IF( AND(SUM(E20:N20)>0,OR(C20=Sheet1!$A$6,C20=Sheet1!$A$3,C20=Sheet1!$A$7,C20=Sheet1!$A$4),D20=Sheet1!$B$31), CONCATENATE(SUM(E20:N20),"台"), IF( AND( SUM(E20:N20)>0, OR(C20=Sheet1!$A$6,C20=Sheet1!$A$3,C20=Sheet1!$A$7,C20=Sheet1!$A$4,C20=Sheet1!$A$5), OR(D20=Sheet1!$B$25,D20=Sheet1!$B$26,D20=Sheet1!$B$27,D20=Sheet1!$B$28,D20=Sheet1!$B$29,D20=Sheet1!$B$30) ), CONCATENATE(SUM(E20:N20),"単位"), "" ) ) ) | P20: =C20&D20 | Q20: =SUM(E20:N20) -> 0 | R20: =IF(AND($A20<=DATE(年,4,1),$B20>=DATE(年,7,31)),DATEDIF(DATE(年,4,1),DATE(年,7,31),"d")+1,IF(AND($A20>DATE(年,4,1),$A20<=DATE(年,7,31),$B20>=DATE(年,7,31)),DATEDIF($A20,DATE(年,7,31),"d")+1,IF(AND($A20<=DATE(年,4,1),$B20>=DATE(年,4,1),$B20<=DATE(年,7,31)),DATEDIF(DATE(年,4,1),$B20,"d")+1,IF(AND($A20>=DATE(年,4,1),$A20<=DATE(年,7,31),$B20>=DATE(年,4,1),$B20<=DATE(年,7,31)),DATEDIF(A20,B20,"d")+1,0)))) -> 0 | S20: =IF(AND($A20<=DATE(年,8,1),$B20>=DATE(年,11,30)),DATEDIF(DATE(年,8,1),DATE(年,11,30),"d")+1,IF(AND($A20>DATE(年,8,1),$A20<=DATE(年,11,30),$B20>=DATE(年,11,30)),DATEDIF($A20,DATE(年,11,30),"d")+1,IF(AND($A20<=DATE(年,8,1),$B20>=DATE(年,8,1),$B20<=DATE(年,11,30)),DATEDIF(DATE(年,8,1),$B20,"d")+1,IF(AND($A20>=DATE(年,8,1),$A20<=DATE(年,11,30),$B20>=DATE(年,8,1),$B20<=DATE(年,11,30)),DATEDIF($A20,$B20,"d")+1,0)))) -> 0 | T20: =IF(AND($A20<=DATE(年,12,1),$B20>=DATE(年+1,3,31)),DATEDIF(DATE(年,12,1),DATE(年+1,3,31),"d")+1,IF(AND($A20>DATE(年,12,1),$A20<=DATE(年+1,3,31),$B20>=DATE(年+1,3,31)),DATEDIF($A20,DATE(年+1,3,31),"d")+1,IF(AND($A20<=DATE(年,12,1),$B20>=DATE(年,12,1),$B20<=DATE(年+1,3,31)),DATEDIF(DATE(年,12,1),$B20,"d")+1,IF(AND(A20>=DATE(年,12,1),$A20<=DATE(年+1,3,31),$B20>=DATE(年,12,1),$B20<=DATE(年+1,3,31)),DATEDIF($A20,$B20,"d")+1,0)))) -> 0 | U20: =IF( AND($P20=ストレージ一般解析Quota設定のみ,$Q20<=30),0,IF( AND($P20=ストレージ一般解析Quota設定のみ,$Q20>30),ROUNDDOWN(ROUNDDOWN(ROUNDUP($Q20/10,0)*ストレージ一般解析Quota設定のみ単価*(R20/年間日数),0)*消費税,0),IF( AND($P20=ストレージ個人ゲノムQuota設定のみ),ROUNDDOWN(ROUNDDOWN(ROUNDUP($Q20/10,0)*ストレージ個人ゲノムQuota設定のみ単価*(R20/年間日数),0)*消費税,0),IF( $D20=CPU1_,ROUNDDOWN(ROUNDDOWN(($Q20*CPU9単価*R20/30),0)*消費税,0),IF( $D20=CPU2_,ROUNDDOWN(ROUNDDOWN(($Q20*CPU10単価*R20/30),0)*消費税,0),IF( $D20=Mem1_,ROUNDDOWN(ROUNDDOWN(($Q20*Mem1単価*R20/30),0)*消費税,0),IF( $D20=Mem2_,ROUNDDOWN(ROUNDDOWN(($Q20*Mem2単価*R20/30),0)*消費税,0),IF( $D20=Acc1_,ROUNDDOWN(ROUNDDOWN(($Q20*Acc1単価*R20/30),0)*消費税,0),IF( $D20=Acc2_,ROUNDDOWN(ROUNDDOWN(($Q20*Acc2単価*R20/30),0)*消費税,0),IF( $D20=Acc3_,ROUNDDOWN(ROUNDDOWN(($Q20*Acc3単価*R20/30),0)*消費税,0),"" ) ) ) ) ) ) ) ) ) ) | V20: =IF( AND($P20=ストレージ一般解析Quota設定のみ,$Q20<=30),0,IF( AND($P20=ストレージ一般解析Quota設定のみ,$Q20>30),ROUNDDOWN(ROUNDDOWN(ROUNDUP($Q20/10,0)*ストレージ一般解析Quota設定のみ単価*(S20/年間日数),0)*消費税,0),IF( AND($P20=ストレージ個人ゲノムQuota設定のみ),ROUNDDOWN(ROUNDDOWN(ROUNDUP($Q20/10,0)*ストレージ個人ゲノムQuota設定のみ単価*(S20/年間日数),0)*消費税,0),IF( $D20=CPU1_,ROUNDDOWN(ROUNDDOWN(($Q20*CPU9単価*S20/30),0)*消費税,0),IF( $D20=CPU2_,ROUNDDOWN(ROUNDDOWN(($Q20*CPU10単価*S20/30),0)*消費税,0),IF( $D20=Mem1_,ROUNDDOWN(ROUNDDOWN(($Q20*Mem1単価*S20/30),0)*消費税,0),IF( $D20=Mem2_,ROUNDDOWN(ROUNDDOWN(($Q20*Mem2単価*S20/30),0)*消費税,0),IF( $D20=Acc1_,ROUNDDOWN(ROUNDDOWN(($Q20*Acc1単価*S20/30),0)*消費税,0),IF( $D20=Acc2_,ROUNDDOWN(ROUNDDOWN(($Q20*Acc2単価*S20/30),0)*消費税,0),IF( $D20=Acc3_,ROUNDDOWN(ROUNDDOWN(($Q20*Acc3単価*S20/30),0)*消費税,0),"" ) ) ) ) ) ) ) ) ) ) | W20: =IF( AND($P20=ストレージ一般解析Quota設定のみ,$Q20<=30),0,IF( AND($P20=ストレージ一般解析Quota設定のみ,$Q20>30),ROUNDDOWN(ROUNDDOWN(ROUNDUP($Q20/10,0)*ストレージ一般解析Quota設定のみ単価*(T20/年間日数),0)*消費税,0),IF( AND($P20=ストレージ個人ゲノムQuota設定のみ),ROUNDDOWN(ROUNDDOWN(ROUNDUP($Q20/10,0)*ストレージ個人ゲノムQuota設定のみ単価*(T20/年間日数),0)*消費税,0),IF( $D20=CPU1_,ROUNDDOWN(ROUNDDOWN(($Q20*CPU9単価*T20/30),0)*消費税,0),IF( $D20=CPU2_,ROUNDDOWN(ROUNDDOWN(($Q20*CPU10単価*T20/30),0)*消費税,0),IF( $D20=Mem1_,ROUNDDOWN(ROUNDDOWN(($Q20*Mem1単価*T20/30),0)*消費税,0),IF( $D20=Mem2_,ROUNDDOWN(ROUNDDOWN(($Q20*Mem2単価*T20/30),0)*消費税,0),IF( $D20=Acc1_,ROUNDDOWN(ROUNDDOWN(($Q20*Acc1単価*T20/30),0)*消費税,0),IF( $D20=Acc2_,ROUNDDOWN(ROUNDDOWN(($Q20*Acc2単価*T20/30),0)*消費税,0),IF( $D20=Acc3_,ROUNDDOWN(ROUNDDOWN(($Q20*Acc3単価*T20/30),0)*消費税,0),"" ) ) ) ) ) ) ) ) ) )
O21: =IF( AND(SUM(E21:N21)>0,OR(C21=Sheet1!$A$1,C21=Sheet1!$A$2)), CONCATENATE(SUM(E21:N21),"TB"), IF( AND(SUM(E21:N21)>0,OR(C21=Sheet1!$A$6,C21=Sheet1!$A$3,C21=Sheet1!$A$7,C21=Sheet1!$A$4),D21=Sheet1!$B$31), CONCATENATE(SUM(E21:N21),"台"), IF( AND( SUM(E21:N21)>0, OR(C21=Sheet1!$A$6,C21=Sheet1!$A$3,C21=Sheet1!$A$7,C21=Sheet1!$A$4,C21=Sheet1!$A$5), OR(D21=Sheet1!$B$25,D21=Sheet1!$B$26,D21=Sheet1!$B$27,D21=Sheet1!$B$28,D21=Sheet1!$B$29,D21=Sheet1!$B$30) ), CONCATENATE(SUM(E21:N21),"単位"), "" ) ) ) | P21: =C21&D21 | Q21: =SUM(E21:N21) -> 0 | R21: =IF(AND($A21<=DATE(年,4,1),$B21>=DATE(年,7,31)),DATEDIF(DATE(年,4,1),DATE(年,7,31),"d")+1,IF(AND($A21>DATE(年,4,1),$A21<=DATE(年,7,31),$B21>=DATE(年,7,31)),DATEDIF($A21,DATE(年,7,31),"d")+1,IF(AND($A21<=DATE(年,4,1),$B21>=DATE(年,4,1),$B21<=DATE(年,7,31)),DATEDIF(DATE(年,4,1),$B21,"d")+1,IF(AND($A21>=DATE(年,4,1),$A21<=DATE(年,7,31),$B21>=DATE(年,4,1),$B21<=DATE(年,7,31)),DATEDIF(A21,B21,"d")+1,0)))) -> 0 | S21: =IF(AND($A21<=DATE(年,8,1),$B21>=DATE(年,11,30)),DATEDIF(DATE(年,8,1),DATE(年,11,30),"d")+1,IF(AND($A21>DATE(年,8,1),$A21<=DATE(年,11,30),$B21>=DATE(年,11,30)),DATEDIF($A21,DATE(年,11,30),"d")+1,IF(AND($A21<=DATE(年,8,1),$B21>=DATE(年,8,1),$B21<=DATE(年,11,30)),DATEDIF(DATE(年,8,1),$B21,"d")+1,IF(AND($A21>=DATE(年,8,1),$A21<=DATE(年,11,30),$B21>=DATE(年,8,1),$B21<=DATE(年,11,30)),DATEDIF($A21,$B21,"d")+1,0)))) -> 0 | T21: =IF(AND($A21<=DATE(年,12,1),$B21>=DATE(年+1,3,31)),DATEDIF(DATE(年,12,1),DATE(年+1,3,31),"d")+1,IF(AND($A21>DATE(年,12,1),$A21<=DATE(年+1,3,31),$B21>=DATE(年+1,3,31)),DATEDIF($A21,DATE(年+1,3,31),"d")+1,IF(AND($A21<=DATE(年,12,1),$B21>=DATE(年,12,1),$B21<=DATE(年+1,3,31)),DATEDIF(DATE(年,12,1),$B21,"d")+1,IF(AND(A21>=DATE(年,12,1),$A21<=DATE(年+1,3,31),$B21>=DATE(年,12,1),$B21<=DATE(年+1,3,31)),DATEDIF($A21,$B21,"d")+1,0)))) -> 0 | U21: =IF( AND($P21=ストレージ一般解析Quota設定のみ,$Q21<=30),0,IF( AND($P21=ストレージ一般解析Quota設定のみ,$Q21>30),ROUNDDOWN(ROUNDDOWN(ROUNDUP($Q21/10,0)*ストレージ一般解析Quota設定のみ単価*(R21/年間日数),0)*消費税,0),IF( AND($P21=ストレージ個人ゲノムQuota設定のみ),ROUNDDOWN(ROUNDDOWN(ROUNDUP($Q21/10,0)*ストレージ個人ゲノムQuota設定のみ単価*(R21/年間日数),0)*消費税,0),IF( $D21=CPU1_,ROUNDDOWN(ROUNDDOWN(($Q21*CPU10単価*R21/30),0)*消費税,0),IF( $D21=CPU2_,ROUNDDOWN(ROUNDDOWN(($Q21*CPU11単価*R21/30),0)*消費税,0),IF( $D21=Mem1_,ROUNDDOWN(ROUNDDOWN(($Q21*Mem1単価*R21/30),0)*消費税,0),IF( $D21=Mem2_,ROUNDDOWN(ROUNDDOWN(($Q21*Mem2単価*R21/30),0)*消費税,0),IF( $D21=Acc1_,ROUNDDOWN(ROUNDDOWN(($Q21*Acc1単価*R21/30),0)*消費税,0),IF( $D21=Acc2_,ROUNDDOWN(ROUNDDOWN(($Q21*Acc2単価*R21/30),0)*消費税,0),IF( $D21=Acc3_,ROUNDDOWN(ROUNDDOWN(($Q21*Acc3単価*R21/30),0)*消費税,0),"" ) ) ) ) ) ) ) ) ) ) | V21: =IF( AND($P21=ストレージ一般解析Quota設定のみ,$Q21<=30),0,IF( AND($P21=ストレージ一般解析Quota設定のみ,$Q21>30),ROUNDDOWN(ROUNDDOWN(ROUNDUP($Q21/10,0)*ストレージ一般解析Quota設定のみ単価*(S21/年間日数),0)*消費税,0),IF( AND($P21=ストレージ個人ゲノムQuota設定のみ),ROUNDDOWN(ROUNDDOWN(ROUNDUP($Q21/10,0)*ストレージ個人ゲノムQuota設定のみ単価*(S21/年間日数),0)*消費税,0),IF( $D21=CPU1_,ROUNDDOWN(ROUNDDOWN(($Q21*CPU10単価*S21/30),0)*消費税,0),IF( $D21=CPU2_,ROUNDDOWN(ROUNDDOWN(($Q21*CPU11単価*S21/30),0)*消費税,0),IF( $D21=Mem1_,ROUNDDOWN(ROUNDDOWN(($Q21*Mem1単価*S21/30),0)*消費税,0),IF( $D21=Mem2_,ROUNDDOWN(ROUNDDOWN(($Q21*Mem2単価*S21/30),0)*消費税,0),IF( $D21=Acc1_,ROUNDDOWN(ROUNDDOWN(($Q21*Acc1単価*S21/30),0)*消費税,0),IF( $D21=Acc2_,ROUNDDOWN(ROUNDDOWN(($Q21*Acc2単価*S21/30),0)*消費税,0),IF( $D21=Acc3_,ROUNDDOWN(ROUNDDOWN(($Q21*Acc3単価*S21/30),0)*消費税,0),"" ) ) ) ) ) ) ) ) ) ) | W21: =IF( AND($P21=ストレージ一般解析Quota設定のみ,$Q21<=30),0,IF( AND($P21=ストレージ一般解析Quota設定のみ,$Q21>30),ROUNDDOWN(ROUNDDOWN(ROUNDUP($Q21/10,0)*ストレージ一般解析Quota設定のみ単価*(T21/年間日数),0)*消費税,0),IF( AND($P21=ストレージ個人ゲノムQuota設定のみ),ROUNDDOWN(ROUNDDOWN(ROUNDUP($Q21/10,0)*ストレージ個人ゲノムQuota設定のみ単価*(T21/年間日数),0)*消費税,0),IF( $D21=CPU1_,ROUNDDOWN(ROUNDDOWN(($Q21*CPU10単価*T21/30),0)*消費税,0),IF( $D21=CPU2_,ROUNDDOWN(ROUNDDOWN(($Q21*CPU11単価*T21/30),0)*消費税,0),IF( $D21=Mem1_,ROUNDDOWN(ROUNDDOWN(($Q21*Mem1単価*T21/30),0)*消費税,0),IF( $D21=Mem2_,ROUNDDOWN(ROUNDDOWN(($Q21*Mem2単価*T21/30),0)*消費税,0),IF( $D21=Acc1_,ROUNDDOWN(ROUNDDOWN(($Q21*Acc1単価*T21/30),0)*消費税,0),IF( $D21=Acc2_,ROUNDDOWN(ROUNDDOWN(($Q21*Acc2単価*T21/30),0)*消費税,0),IF( $D21=Acc3_,ROUNDDOWN(ROUNDDOWN(($Q21*Acc3単価*T21/30),0)*消費税,0),"" ) ) ) ) ) ) ) ) ) )
O22: =IF( AND(SUM(E22:N22)>0,OR(C22=Sheet1!$A$1,C22=Sheet1!$A$2)), CONCATENATE(SUM(E22:N22),"TB"), IF( AND(SUM(E22:N22)>0,OR(C22=Sheet1!$A$6,C22=Sheet1!$A$3,C22=Sheet1!$A$7,C22=Sheet1!$A$4),D22=Sheet1!$B$31), CONCATENATE(SUM(E22:N22),"台"), IF( AND( SUM(E22:N22)>0, OR(C22=Sheet1!$A$6,C22=Sheet1!$A$3,C22=Sheet1!$A$7,C22=Sheet1!$A$4,C22=Sheet1!$A$5), OR(D22=Sheet1!$B$25,D22=Sheet1!$B$26,D22=Sheet1!$B$27,D22=Sheet1!$B$28,D22=Sheet1!$B$29,D22=Sheet1!$B$30) ), CONCATENATE(SUM(E22:N22),"単位"), "" ) ) ) | P22: =C22&D22 | Q22: =SUM(E22:N22) -> 0 | R22: =IF(AND($A22<=DATE(年,4,1),$B22>=DATE(年,7,31)),DATEDIF(DATE(年,4,1),DATE(年,7,31),"d")+1,IF(AND($A22>DATE(年,4,1),$A22<=DATE(年,7,31),$B22>=DATE(年,7,31)),DATEDIF($A22,DATE(年,7,31),"d")+1,IF(AND($A22<=DATE(年,4,1),$B22>=DATE(年,4,1),$B22<=DATE(年,7,31)),DATEDIF(DATE(年,4,1),$B22,"d")+1,IF(AND($A22>=DATE(年,4,1),$A22<=DATE(年,7,31),$B22>=DATE(年,4,1),$B22<=DATE(年,7,31)),DATEDIF(A22,B22,"d")+1,0)))) -> 0 | S22: =IF(AND($A22<=DATE(年,8,1),$B22>=DATE(年,11,30)),DATEDIF(DATE(年,8,1),DATE(年,11,30),"d")+1,IF(AND($A22>DATE(年,8,1),$A22<=DATE(年,11,30),$B22>=DATE(年,11,30)),DATEDIF($A22,DATE(年,11,30),"d")+1,IF(AND($A22<=DATE(年,8,1),$B22>=DATE(年,8,1),$B22<=DATE(年,11,30)),DATEDIF(DATE(年,8,1),$B22,"d")+1,IF(AND($A22>=DATE(年,8,1),$A22<=DATE(年,11,30),$B22>=DATE(年,8,1),$B22<=DATE(年,11,30)),DATEDIF($A22,$B22,"d")+1,0)))) -> 0 | T22: =IF(AND($A22<=DATE(年,12,1),$B22>=DATE(年+1,3,31)),DATEDIF(DATE(年,12,1),DATE(年+1,3,31),"d")+1,IF(AND($A22>DATE(年,12,1),$A22<=DATE(年+1,3,31),$B22>=DATE(年+1,3,31)),DATEDIF($A22,DATE(年+1,3,31),"d")+1,IF(AND($A22<=DATE(年,12,1),$B22>=DATE(年,12,1),$B22<=DATE(年+1,3,31)),DATEDIF(DATE(年,12,1),$B22,"d")+1,IF(AND(A22>=DATE(年,12,1),$A22<=DATE(年+1,3,31),$B22>=DATE(年,12,1),$B22<=DATE(年+1,3,31)),DATEDIF($A22,$B22,"d")+1,0)))) -> 0 | U22: =IF( AND($P22=ストレージ一般解析Quota設定のみ,$Q22<=30),0,IF( AND($P22=ストレージ一般解析Quota設定のみ,$Q22>30),ROUNDDOWN(ROUNDDOWN(ROUNDUP($Q22/10,0)*ストレージ一般解析Quota設定のみ単価*(R22/年間日数),0)*消費税,0),IF( AND($P22=ストレージ個人ゲノムQuota設定のみ),ROUNDDOWN(ROUNDDOWN(ROUNDUP($Q22/10,0)*ストレージ個人ゲノムQuota設定のみ単価*(R22/年間日数),0)*消費税,0),IF( $D22=CPU1_,ROUNDDOWN(ROUNDDOWN(($Q22*CPU11単価*R22/30),0)*消費税,0),IF( $D22=CPU2_,ROUNDDOWN(ROUNDDOWN(($Q22*CPU12単価*R22/30),0)*消費税,0),IF( $D22=Mem1_,ROUNDDOWN(ROUNDDOWN(($Q22*Mem1単価*R22/30),0)*消費税,0),IF( $D22=Mem2_,ROUNDDOWN(ROUNDDOWN(($Q22*Mem2単価*R22/30),0)*消費税,0),IF( $D22=Acc1_,ROUNDDOWN(ROUNDDOWN(($Q22*Acc1単価*R22/30),0)*消費税,0),IF( $D22=Acc2_,ROUNDDOWN(ROUNDDOWN(($Q22*Acc2単価*R22/30),0)*消費税,0),IF( $D22=Acc3_,ROUNDDOWN(ROUNDDOWN(($Q22*Acc3単価*R22/30),0)*消費税,0),"" ) ) ) ) ) ) ) ) ) ) | V22: =IF( AND($P22=ストレージ一般解析Quota設定のみ,$Q22<=30),0,IF( AND($P22=ストレージ一般解析Quota設定のみ,$Q22>30),ROUNDDOWN(ROUNDDOWN(ROUNDUP($Q22/10,0)*ストレージ一般解析Quota設定のみ単価*(S22/年間日数),0)*消費税,0),IF( AND($P22=ストレージ個人ゲノムQuota設定のみ),ROUNDDOWN(ROUNDDOWN(ROUNDUP($Q22/10,0)*ストレージ個人ゲノムQuota設定のみ単価*(S22/年間日数),0)*消費税,0),IF( $D22=CPU1_,ROUNDDOWN(ROUNDDOWN(($Q22*CPU11単価*S22/30),0)*消費税,0),IF( $D22=CPU2_,ROUNDDOWN(ROUNDDOWN(($Q22*CPU12単価*S22/30),0)*消費税,0),IF( $D22=Mem1_,ROUNDDOWN(ROUNDDOWN(($Q22*Mem1単価*S22/30),0)*消費税,0),IF( $D22=Mem2_,ROUNDDOWN(ROUNDDOWN(($Q22*Mem2単価*S22/30),0)*消費税,0),IF( $D22=Acc1_,ROUNDDOWN(ROUNDDOWN(($Q22*Acc1単価*S22/30),0)*消費税,0),IF( $D22=Acc2_,ROUNDDOWN(ROUNDDOWN(($Q22*Acc2単価*S22/30),0)*消費税,0),IF( $D22=Acc3_,ROUNDDOWN(ROUNDDOWN(($Q22*Acc3単価*S22/30),0)*消費税,0),"" ) ) ) ) ) ) ) ) ) ) | W22: =IF( AND($P22=ストレージ一般解析Quota設定のみ,$Q22<=30),0,IF( AND($P22=ストレージ一般解析Quota設定のみ,$Q22>30),ROUNDDOWN(ROUNDDOWN(ROUNDUP($Q22/10,0)*ストレージ一般解析Quota設定のみ単価*(T22/年間日数),0)*消費税,0),IF( AND($P22=ストレージ個人ゲノムQuota設定のみ),ROUNDDOWN(ROUNDDOWN(ROUNDUP($Q22/10,0)*ストレージ個人ゲノムQuota設定のみ単価*(T22/年間日数),0)*消費税,0),IF( $D22=CPU1_,ROUNDDOWN(ROUNDDOWN(($Q22*CPU11単価*T22/30),0)*消費税,0),IF( $D22=CPU2_,ROUNDDOWN(ROUNDDOWN(($Q22*CPU12単価*T22/30),0)*消費税,0),IF( $D22=Mem1_,ROUNDDOWN(ROUNDDOWN(($Q22*Mem1単価*T22/30),0)*消費税,0),IF( $D22=Mem2_,ROUNDDOWN(ROUNDDOWN(($Q22*Mem2単価*T22/30),0)*消費税,0),IF( $D22=Acc1_,ROUNDDOWN(ROUNDDOWN(($Q22*Acc1単価*T22/30),0)*消費税,0),IF( $D22=Acc2_,ROUNDDOWN(ROUNDDOWN(($Q22*Acc2単価*T22/30),0)*消費税,0),IF( $D22=Acc3_,ROUNDDOWN(ROUNDDOWN(($Q22*Acc3単価*T22/30),0)*消費税,0),"" ) ) ) ) ) ) ) ) ) )
O23: =IF( AND(SUM(E23:N23)>0,OR(C23=Sheet1!$A$1,C23=Sheet1!$A$2)), CONCATENATE(SUM(E23:N23),"TB"), IF( AND(SUM(E23:N23)>0,OR(C23=Sheet1!$A$6,C23=Sheet1!$A$3,C23=Sheet1!$A$7,C23=Sheet1!$A$4),D23=Sheet1!$B$31), CONCATENATE(SUM(E23:N23),"台"), IF( AND( SUM(E23:N23)>0, OR(C23=Sheet1!$A$6,C23=Sheet1!$A$3,C23=Sheet1!$A$7,C23=Sheet1!$A$4,C23=Sheet1!$A$5), OR(D23=Sheet1!$B$25,D23=Sheet1!$B$26,D23=Sheet1!$B$27,D23=Sheet1!$B$28,D23=Sheet1!$B$29,D23=Sheet1!$B$30) ), CONCATENATE(SUM(E23:N23),"単位"), "" ) ) ) | P23: =C23&D23 | Q23: =SUM(E23:N23) -> 0 | R23: =IF(AND($A23<=DATE(年,4,1),$B23>=DATE(年,7,31)),DATEDIF(DATE(年,4,1),DATE(年,7,31),"d")+1,IF(AND($A23>DATE(年,4,1),$A23<=DATE(年,7,31),$B23>=DATE(年,7,31)),DATEDIF($A23,DATE(年,7,31),"d")+1,IF(AND($A23<=DATE(年,4,1),$B23>=DATE(年,4,1),$B23<=DATE(年,7,31)),DATEDIF(DATE(年,4,1),$B23,"d")+1,IF(AND($A23>=DATE(年,4,1),$A23<=DATE(年,7,31),$B23>=DATE(年,4,1),$B23<=DATE(年,7,31)),DATEDIF(A23,B23,"d")+1,0)))) -> 0 | S23: =IF(AND($A23<=DATE(年,8,1),$B23>=DATE(年,11,30)),DATEDIF(DATE(年,8,1),DATE(年,11,30),"d")+1,IF(AND($A23>DATE(年,8,1),$A23<=DATE(年,11,30),$B23>=DATE(年,11,30)),DATEDIF($A23,DATE(年,11,30),"d")+1,IF(AND($A23<=DATE(年,8,1),$B23>=DATE(年,8,1),$B23<=DATE(年,11,30)),DATEDIF(DATE(年,8,1),$B23,"d")+1,IF(AND($A23>=DATE(年,8,1),$A23<=DATE(年,11,30),$B23>=DATE(年,8,1),$B23<=DATE(年,11,30)),DATEDIF($A23,$B23,"d")+1,0)))) -> 0 | T23: =IF(AND($A23<=DATE(年,12,1),$B23>=DATE(年+1,3,31)),DATEDIF(DATE(年,12,1),DATE(年+1,3,31),"d")+1,IF(AND($A23>DATE(年,12,1),$A23<=DATE(年+1,3,31),$B23>=DATE(年+1,3,31)),DATEDIF($A23,DATE(年+1,3,31),"d")+1,IF(AND($A23<=DATE(年,12,1),$B23>=DATE(年,12,1),$B23<=DATE(年+1,3,31)),DATEDIF(DATE(年,12,1),$B23,"d")+1,IF(AND(A23>=DATE(年,12,1),$A23<=DATE(年+1,3,31),$B23>=DATE(年,12,1),$B23<=DATE(年+1,3,31)),DATEDIF($A23,$B23,"d")+1,0)))) -> 0 | U23: =IF( AND($P23=ストレージ一般解析Quota設定のみ,$Q23<=30),0,IF( AND($P23=ストレージ一般解析Quota設定のみ,$Q23>30),ROUNDDOWN(ROUNDDOWN(ROUNDUP($Q23/10,0)*ストレージ一般解析Quota設定のみ単価*(R23/年間日数),0)*消費税,0),IF( AND($P23=ストレージ個人ゲノムQuota設定のみ),ROUNDDOWN(ROUNDDOWN(ROUNDUP($Q23/10,0)*ストレージ個人ゲノムQuota設定のみ単価*(R23/年間日数),0)*消費税,0),IF( $D23=CPU1_,ROUNDDOWN(ROUNDDOWN(($Q23*CPU12単価*R23/30),0)*消費税,0),IF( $D23=CPU2_,ROUNDDOWN(ROUNDDOWN(($Q23*CPU13単価*R23/30),0)*消費税,0),IF( $D23=Mem1_,ROUNDDOWN(ROUNDDOWN(($Q23*Mem1単価*R23/30),0)*消費税,0),IF( $D23=Mem2_,ROUNDDOWN(ROUNDDOWN(($Q23*Mem2単価*R23/30),0)*消費税,0),IF( $D23=Acc1_,ROUNDDOWN(ROUNDDOWN(($Q23*Acc1単価*R23/30),0)*消費税,0),IF( $D23=Acc2_,ROUNDDOWN(ROUNDDOWN(($Q23*Acc2単価*R23/30),0)*消費税,0),IF( $D23=Acc3_,ROUNDDOWN(ROUNDDOWN(($Q23*Acc3単価*R23/30),0)*消費税,0),"" ) ) ) ) ) ) ) ) ) ) | V23: =IF( AND($P23=ストレージ一般解析Quota設定のみ,$Q23<=30),0,IF( AND($P23=ストレージ一般解析Quota設定のみ,$Q23>30),ROUNDDOWN(ROUNDDOWN(ROUNDUP($Q23/10,0)*ストレージ一般解析Quota設定のみ単価*(S23/年間日数),0)*消費税,0),IF( AND($P23=ストレージ個人ゲノムQuota設定のみ),ROUNDDOWN(ROUNDDOWN(ROUNDUP($Q23/10,0)*ストレージ個人ゲノムQuota設定のみ単価*(S23/年間日数),0)*消費税,0),IF( $D23=CPU1_,ROUNDDOWN(ROUNDDOWN(($Q23*CPU12単価*S23/30),0)*消費税,0),IF( $D23=CPU2_,ROUNDDOWN(ROUNDDOWN(($Q23*CPU13単価*S23/30),0)*消費税,0),IF( $D23=Mem1_,ROUNDDOWN(ROUNDDOWN(($Q23*Mem1単価*S23/30),0)*消費税,0),IF( $D23=Mem2_,ROUNDDOWN(ROUNDDOWN(($Q23*Mem2単価*S23/30),0)*消費税,0),IF( $D23=Acc1_,ROUNDDOWN(ROUNDDOWN(($Q23*Acc1単価*S23/30),0)*消費税,0),IF( $D23=Acc2_,ROUNDDOWN(ROUNDDOWN(($Q23*Acc2単価*S23/30),0)*消費税,0),IF( $D23=Acc3_,ROUNDDOWN(ROUNDDOWN(($Q23*Acc3単価*S23/30),0)*消費税,0),"" ) ) ) ) ) ) ) ) ) ) | W23: =IF( AND($P23=ストレージ一般解析Quota設定のみ,$Q23<=30),0,IF( AND($P23=ストレージ一般解析Quota設定のみ,$Q23>30),ROUNDDOWN(ROUNDDOWN(ROUNDUP($Q23/10,0)*ストレージ一般解析Quota設定のみ単価*(T23/年間日数),0)*消費税,0),IF( AND($P23=ストレージ個人ゲノムQuota設定のみ),ROUNDDOWN(ROUNDDOWN(ROUNDUP($Q23/10,0)*ストレージ個人ゲノムQuota設定のみ単価*(T23/年間日数),0)*消費税,0),IF( $D23=CPU1_,ROUNDDOWN(ROUNDDOWN(($Q23*CPU12単価*T23/30),0)*消費税,0),IF( $D23=CPU2_,ROUNDDOWN(ROUNDDOWN(($Q23*CPU13単価*T23/30),0)*消費税,0),IF( $D23=Mem1_,ROUNDDOWN(ROUNDDOWN(($Q23*Mem1単価*T23/30),0)*消費税,0),IF( $D23=Mem2_,ROUNDDOWN(ROUNDDOWN(($Q23*Mem2単価*T23/30),0)*消費税,0),IF( $D23=Acc1_,ROUNDDOWN(ROUNDDOWN(($Q23*Acc1単価*T23/30),0)*消費税,0),IF( $D23=Acc2_,ROUNDDOWN(ROUNDDOWN(($Q23*Acc2単価*T23/30),0)*消費税,0),IF( $D23=Acc3_,ROUNDDOWN(ROUNDDOWN(($Q23*Acc3単価*T23/30),0)*消費税,0),"" ) ) ) ) ) ) ) ) ) )
O24: =IF( AND(SUM(E24:N24)>0,OR(C24=Sheet1!$A$1,C24=Sheet1!$A$2)), CONCATENATE(SUM(E24:N24),"TB"), IF( AND(SUM(E24:N24)>0,OR(C24=Sheet1!$A$6,C24=Sheet1!$A$3,C24=Sheet1!$A$7,C24=Sheet1!$A$4),D24=Sheet1!$B$31), CONCATENATE(SUM(E24:N24),"台"), IF( AND( SUM(E24:N24)>0, OR(C24=Sheet1!$A$6,C24=Sheet1!$A$3,C24=Sheet1!$A$7,C24=Sheet1!$A$4,C24=Sheet1!$A$5), OR(D24=Sheet1!$B$25,D24=Sheet1!$B$26,D24=Sheet1!$B$27,D24=Sheet1!$B$28,D24=Sheet1!$B$29,D24=Sheet1!$B$30) ), CONCATENATE(SUM(E24:N24),"単位"), "" ) ) ) | P24: =C24&D24 | Q24: =SUM(E24:N24) -> 0 | R24: =IF(AND($A24<=DATE(年,4,1),$B24>=DATE(年,7,31)),DATEDIF(DATE(年,4,1),DATE(年,7,31),"d")+1,IF(AND($A24>DATE(年,4,1),$A24<=DATE(年,7,31),$B24>=DATE(年,7,31)),DATEDIF($A24,DATE(年,7,31),"d")+1,IF(AND($A24<=DATE(年,4,1),$B24>=DATE(年,4,1),$B24<=DATE(年,7,31)),DATEDIF(DATE(年,4,1),$B24,"d")+1,IF(AND($A24>=DATE(年,4,1),$A24<=DATE(年,7,31),$B24>=DATE(年,4,1),$B24<=DATE(年,7,31)),DATEDIF(A24,B24,"d")+1,0)))) -> 0 | S24: =IF(AND($A24<=DATE(年,8,1),$B24>=DATE(年,11,30)),DATEDIF(DATE(年,8,1),DATE(年,11,30),"d")+1,IF(AND($A24>DATE(年,8,1),$A24<=DATE(年,11,30),$B24>=DATE(年,11,30)),DATEDIF($A24,DATE(年,11,30),"d")+1,IF(AND($A24<=DATE(年,8,1),$B24>=DATE(年,8,1),$B24<=DATE(年,11,30)),DATEDIF(DATE(年,8,1),$B24,"d")+1,IF(AND($A24>=DATE(年,8,1),$A24<=DATE(年,11,30),$B24>=DATE(年,8,1),$B24<=DATE(年,11,30)),DATEDIF($A24,$B24,"d")+1,0)))) -> 0 | T24: =IF(AND($A24<=DATE(年,12,1),$B24>=DATE(年+1,3,31)),DATEDIF(DATE(年,12,1),DATE(年+1,3,31),"d")+1,IF(AND($A24>DATE(年,12,1),$A24<=DATE(年+1,3,31),$B24>=DATE(年+1,3,31)),DATEDIF($A24,DATE(年+1,3,31),"d")+1,IF(AND($A24<=DATE(年,12,1),$B24>=DATE(年,12,1),$B24<=DATE(年+1,3,31)),DATEDIF(DATE(年,12,1),$B24,"d")+1,IF(AND(A24>=DATE(年,12,1),$A24<=DATE(年+1,3,31),$B24>=DATE(年,12,1),$B24<=DATE(年+1,3,31)),DATEDIF($A24,$B24,"d")+1,0)))) -> 0 | U24: =IF( AND($P24=ストレージ一般解析Quota設定のみ,$Q24<=30),0,IF( AND($P24=ストレージ一般解析Quota設定のみ,$Q24>30),ROUNDDOWN(ROUNDDOWN(ROUNDUP($Q24/10,0)*ストレージ一般解析Quota設定のみ単価*(R24/年間日数),0)*消費税,0),IF( AND($P24=ストレージ個人ゲノムQuota設定のみ),ROUNDDOWN(ROUNDDOWN(ROUNDUP($Q24/10,0)*ストレージ個人ゲノムQuota設定のみ単価*(R24/年間日数),0)*消費税,0),IF( $D24=CPU1_,ROUNDDOWN(ROUNDDOWN(($Q24*CPU13単価*R24/30),0)*消費税,0),IF( $D24=CPU2_,ROUNDDOWN(ROUNDDOWN(($Q24*CPU14単価*R24/30),0)*消費税,0),IF( $D24=Mem1_,ROUNDDOWN(ROUNDDOWN(($Q24*Mem1単価*R24/30),0)*消費税,0),IF( $D24=Mem2_,ROUNDDOWN(ROUNDDOWN(($Q24*Mem2単価*R24/30),0)*消費税,0),IF( $D24=Acc1_,ROUNDDOWN(ROUNDDOWN(($Q24*Acc1単価*R24/30),0)*消費税,0),IF( $D24=Acc2_,ROUNDDOWN(ROUNDDOWN(($Q24*Acc2単価*R24/30),0)*消費税,0),IF( $D24=Acc3_,ROUNDDOWN(ROUNDDOWN(($Q24*Acc3単価*R24/30),0)*消費税,0),"" ) ) ) ) ) ) ) ) ) ) | V24: =IF( AND($P24=ストレージ一般解析Quota設定のみ,$Q24<=30),0,IF( AND($P24=ストレージ一般解析Quota設定のみ,$Q24>30),ROUNDDOWN(ROUNDDOWN(ROUNDUP($Q24/10,0)*ストレージ一般解析Quota設定のみ単価*(S24/年間日数),0)*消費税,0),IF( AND($P24=ストレージ個人ゲノムQuota設定のみ),ROUNDDOWN(ROUNDDOWN(ROUNDUP($Q24/10,0)*ストレージ個人ゲノムQuota設定のみ単価*(S24/年間日数),0)*消費税,0),IF( $D24=CPU1_,ROUNDDOWN(ROUNDDOWN(($Q24*CPU13単価*S24/30),0)*消費税,0),IF( $D24=CPU2_,ROUNDDOWN(ROUNDDOWN(($Q24*CPU14単価*S24/30),0)*消費税,0),IF( $D24=Mem1_,ROUNDDOWN(ROUNDDOWN(($Q24*Mem1単価*S24/30),0)*消費税,0),IF( $D24=Mem2_,ROUNDDOWN(ROUNDDOWN(($Q24*Mem2単価*S24/30),0)*消費税,0),IF( $D24=Acc1_,ROUNDDOWN(ROUNDDOWN(($Q24*Acc1単価*S24/30),0)*消費税,0),IF( $D24=Acc2_,ROUNDDOWN(ROUNDDOWN(($Q24*Acc2単価*S24/30),0)*消費税,0),IF( $D24=Acc3_,ROUNDDOWN(ROUNDDOWN(($Q24*Acc3単価*S24/30),0)*消費税,0),"" ) ) ) ) ) ) ) ) ) ) | W24: =IF( AND($P24=ストレージ一般解析Quota設定のみ,$Q24<=30),0,IF( AND($P24=ストレージ一般解析Quota設定のみ,$Q24>30),ROUNDDOWN(ROUNDDOWN(ROUNDUP($Q24/10,0)*ストレージ一般解析Quota設定のみ単価*(T24/年間日数),0)*消費税,0),IF( AND($P24=ストレージ個人ゲノムQuota設定のみ),ROUNDDOWN(ROUNDDOWN(ROUNDUP($Q24/10,0)*ストレージ個人ゲノムQuota設定のみ単価*(T24/年間日数),0)*消費税,0),IF( $D24=CPU1_,ROUNDDOWN(ROUNDDOWN(($Q24*CPU13単価*T24/30),0)*消費税,0),IF( $D24=CPU2_,ROUNDDOWN(ROUNDDOWN(($Q24*CPU14単価*T24/30),0)*消費税,0),IF( $D24=Mem1_,ROUNDDOWN(ROUNDDOWN(($Q24*Mem1単価*T24/30),0)*消費税,0),IF( $D24=Mem2_,ROUNDDOWN(ROUNDDOWN(($Q24*Mem2単価*T24/30),0)*消費税,0),IF( $D24=Acc1_,ROUNDDOWN(ROUNDDOWN(($Q24*Acc1単価*T24/30),0)*消費税,0),IF( $D24=Acc2_,ROUNDDOWN(ROUNDDOWN(($Q24*Acc2単価*T24/30),0)*消費税,0),IF( $D24=Acc3_,ROUNDDOWN(ROUNDDOWN(($Q24*Acc3単価*T24/30),0)*消費税,0),"" ) ) ) ) ) ) ) ) ) )
... O26: =IF( AND(SUM(E26:N26)>0,OR(C26=Sheet1!$A$1,C26=Sheet1!$A$2)), CONCATENATE(SUM(E26:N26),"TB"), IF( AND(SUM(E26:N26)>0,OR(C26=Sheet1!$A$6,C26=Sheet1!$A$3,C26=Sheet1!$A$7,C26=Sheet1!$A$4),D26=Sheet1!$B$31), CONCATENATE(SUM(E26:N26),"台"), IF( AND( SUM(E26:N26)>0, OR(C26=Sheet1!$A$6,C26=Sheet1!$A$3,C26=Sheet1!$A$7,C26=Sheet1!$A$4,C26=Sheet1!$A$5), OR(D26=Sheet1!$B$25,D26=Sheet1!$B$26,D26=Sheet1!$B$27,D26=Sheet1!$B$28,D26=Sheet1!$B$29,D26=Sheet1!$B$30) ), CONCATENATE(SUM(E26:N26),"単位"), "" ) ) ) | P26: =C26&D26 | Q26: =SUM(E26:N26) -> 0 | R26: =IF(AND($A26<=DATE(年,4,1),$B26>=DATE(年,7,31)),DATEDIF(DATE(年,4,1),DATE(年,7,31),"d")+1,IF(AND($A26>DATE(年,4,1),$A26<=DATE(年,7,31),$B26>=DATE(年,7,31)),DATEDIF($A26,DATE(年,7,31),"d")+1,IF(AND($A26<=DATE(年,4,1),$B26>=DATE(年,4,1),$B26<=DATE(年,7,31)),DATEDIF(DATE(年,4,1),$B26,"d")+1,IF(AND($A26>=DATE(年,4,1),$A26<=DATE(年,7,31),$B26>=DATE(年,4,1),$B26<=DATE(年,7,31)),DATEDIF(A26,B26,"d")+1,0)))) -> 0 | S26: =IF(AND($A26<=DATE(年,8,1),$B26>=DATE(年,11,30)),DATEDIF(DATE(年,8,1),DATE(年,11,30),"d")+1,IF(AND($A26>DATE(年,8,1),$A26<=DATE(年,11,30),$B26>=DATE(年,11,30)),DATEDIF($A26,DATE(年,11,30),"d")+1,IF(AND($A26<=DATE(年,8,1),$B26>=DATE(年,8,1),$B26<=DATE(年,11,30)),DATEDIF(DATE(年,8,1),$B26,"d")+1,IF(AND($A26>=DATE(年,8,1),$A26<=DATE(年,11,30),$B26>=DATE(年,8,1),$B26<=DATE(年,11,30)),DATEDIF($A26,$B26,"d")+1,0)))) -> 0 | T26: =IF(AND($A26<=DATE(年,12,1),$B26>=DATE(年+1,3,31)),DATEDIF(DATE(年,12,1),DATE(年+1,3,31),"d")+1,IF(AND($A26>DATE(年,12,1),$A26<=DATE(年+1,3,31),$B26>=DATE(年+1,3,31)),DATEDIF($A26,DATE(年+1,3,31),"d")+1,IF(AND($A26<=DATE(年,12,1),$B26>=DATE(年,12,1),$B26<=DATE(年+1,3,31)),DATEDIF(DATE(年,12,1),$B26,"d")+1,IF(AND(A26>=DATE(年,12,1),$A26<=DATE(年+1,3,31),$B26>=DATE(年,12,1),$B26<=DATE(年+1,3,31)),DATEDIF($A26,$B26,"d")+1,0)))) -> 0 | U26: =IF( AND($P26=ストレージ一般解析Quota設定のみ,$Q26<=30),0,IF( AND($P26=ストレージ一般解析Quota設定のみ,$Q26>30),ROUNDDOWN(ROUNDDOWN(ROUNDUP($Q26/10,0)*ストレージ一般解析Quota設定のみ単価*(R26/年間日数),0)*消費税,0),IF( AND($P26=ストレージ個人ゲノムQuota設定のみ),ROUNDDOWN(ROUNDDOWN(ROUNDUP($Q26/10,0)*ストレージ個人ゲノムQuota設定のみ単価*(R26/年間日数),0)*消費税,0),IF( $D26=CPU1_,ROUNDDOWN(ROUNDDOWN(($Q26*CPU15単価*R26/30),0)*消費税,0),IF( $D26=CPU2_,ROUNDDOWN(ROUNDDOWN(($Q26*CPU16単価*R26/30),0)*消費税,0),IF( $D26=Mem1_,ROUNDDOWN(ROUNDDOWN(($Q26*Mem1単価*R26/30),0)*消費税,0),IF( $D26=Mem2_,ROUNDDOWN(ROUNDDOWN(($Q26*Mem2単価*R26/30),0)*消費税,0),IF( $D26=Acc1_,ROUNDDOWN(ROUNDDOWN(($Q26*Acc1単価*R26/30),0)*消費税,0),IF( $D26=Acc2_,ROUNDDOWN(ROUNDDOWN(($Q26*Acc2単価*R26/30),0)*消費税,0),IF( $D26=Acc3_,ROUNDDOWN(ROUNDDOWN(($Q26*Acc3単価*R26/30),0)*消費税,0),"" ) ) ) ) ) ) ) ) ) ) | V26: =IF( AND($P26=ストレージ一般解析Quota設定のみ,$Q26<=30),0,IF( AND($P26=ストレージ一般解析Quota設定のみ,$Q26>30),ROUNDDOWN(ROUNDDOWN(ROUNDUP($Q26/10,0)*ストレージ一般解析Quota設定のみ単価*(S26/年間日数),0)*消費税,0),IF( AND($P26=ストレージ個人ゲノムQuota設定のみ),ROUNDDOWN(ROUNDDOWN(ROUNDUP($Q26/10,0)*ストレージ個人ゲノムQuota設定のみ単価*(S26/年間日数),0)*消費税,0),IF( $D26=CPU1_,ROUNDDOWN(ROUNDDOWN(($Q26*CPU15単価*S26/30),0)*消費税,0),IF( $D26=CPU2_,ROUNDDOWN(ROUNDDOWN(($Q26*CPU16単価*S26/30),0)*消費税,0),IF( $D26=Mem1_,ROUNDDOWN(ROUNDDOWN(($Q26*Mem1単価*S26/30),0)*消費税,0),IF( $D26=Mem2_,ROUNDDOWN(ROUNDDOWN(($Q26*Mem2単価*S26/30),0)*消費税,0),IF( $D26=Acc1_,ROUNDDOWN(ROUNDDOWN(($Q26*Acc1単価*S26/30),0)*消費税,0),IF( $D26=Acc2_,ROUNDDOWN(ROUNDDOWN(($Q26*Acc2単価*S26/30),0)*消費税,0),IF( $D26=Acc3_,ROUNDDOWN(ROUNDDOWN(($Q26*Acc3単価*S26/30),0)*消費税,0),"" ) ) ) ) ) ) ) ) ) ) | W26: =IF( AND($P26=ストレージ一般解析Quota設定のみ,$Q26<=30),0,IF( AND($P26=ストレージ一般解析Quota設定のみ,$Q26>30),ROUNDDOWN(ROUNDDOWN(ROUNDUP($Q26/10,0)*ストレージ一般解析Quota設定のみ単価*(T26/年間日数),0)*消費税,0),IF( AND($P26=ストレージ個人ゲノムQuota設定のみ),ROUNDDOWN(ROUNDDOWN(ROUNDUP($Q26/10,0)*ストレージ個人ゲノムQuota設定のみ単価*(T26/年間日数),0)*消費税,0),IF( $D26=CPU1_,ROUNDDOWN(ROUNDDOWN(($Q26*CPU15単価*T26/30),0)*消費税,0),IF( $D26=CPU2_,ROUNDDOWN(ROUNDDOWN(($Q26*CPU16単価*T26/30),0)*消費税,0),IF( $D26=Mem1_,ROUNDDOWN(ROUNDDOWN(($Q26*Mem1単価*T26/30),0)*消費税,0),IF( $D26=Mem2_,ROUNDDOWN(ROUNDDOWN(($Q26*Mem2単価*T26/30),0)*消費税,0),IF( $D26=Acc1_,ROUNDDOWN(ROUNDDOWN(($Q26*Acc1単価*T26/30),0)*消費税,0),IF( $D26=Acc2_,ROUNDDOWN(ROUNDDOWN(($Q26*Acc2単価*T26/30),0)*消費税,0),IF( $D26=Acc3_,ROUNDDOWN(ROUNDDOWN(($Q26*Acc3単価*T26/30),0)*消費税,0),"" ) ) ) ) ) ) ) ) ) )
A27: 計算ノード優先利用_一般解析区画 料金合計 | U27: =SUMIFS(U12:U26,$C12:$C26,Sheet1!$A$6) -> 0 | V27: =SUMIFS(V12:V26,$C12:$C26,Sheet1!$A$6) -> 0 | W27: =SUMIFS(W12:W26,$C12:$C26,Sheet1!$A$6) -> 0
A28: 計算ノード占有利用_一般解析区画 料金合計 | U28: =SUMIFS(U12:U26,$C12:$C26,Sheet1!$A$3) -> 0 | V28: =SUMIFS(V12:V26,$C12:$C26,Sheet1!$A$3) -> 0 | W28: =SUMIFS(W12:W26,$C12:$C26,Sheet1!$A$3) -> 0
A29: 計算ノード優先利用_個人ゲノム区画 料金合計 | U29: =SUMIFS(U12:U26,$C12:$C26,Sheet1!$A$7) -> 0 | V29: =SUMIFS(V12:V26,$C12:$C26,Sheet1!$A$7) -> 0 | W29: =SUMIFS(W12:W26,$C12:$C26,Sheet1!$A$7) -> 0
